Workbook

Sheet Summary
A1: rAGMF & FHL Loans - Interest Paid vs Payable
A2: 800 Super GAEA (Cambodia) Co., Ltd. | Lender basis, reconciled to lender exposure calc 30/06/2026 and Amendment cl. 3.8 | USD
A3: Reporting date: | B3: =Inputs!B18 -> 46300 | C3: Default interest after 30/06/2026: | E3: =IF(Inputs!B20=1,"Continues","Stopped") -> Continues
A5: 1. Position at reporting date (accrual to day before reporting date)
A6: USD | B6: rAGMF | C6: FHL | D6: Total | E6: Note
A7: Principal outstanding | B7: =Inputs!B9-SUMIFS(Cash_Events!$G$6:$G$20,Cash_Events!$C$6:$C$20,"rAGMF",Cash_Events!$B$6:$B$20,"<"&Inputs!$B$18) -> 735000 | C7: =Inputs!C9-SUMIFS(Cash_Events!$G$6:$G$20,Cash_Events!$C$6:$C$20,"FHL",Cash_Events!$B$6:$B$20,"<"&Inputs!$B$18) -> 735000 | D7: =B7+C7 -> 1470000
A8: Regular interest payable | B8: =SUMIFS(Daily!$G$6:$G$2400,Daily!$A$6:$A$2400,"<"&Inputs!$B$18)-SUMIFS(Cash_Events!$H$6:$H$20,Cash_Events!$C$6:$C$20,"rAGMF",Cash_Events!$B$6:$B$20,"<"&Inputs!$B$18) -> 318304.07 | C8: =SUMIFS(Daily!$L$6:$L$2400,Daily!$A$6:$A$2400,"<"&Inputs!$B$18)-SUMIFS(Cash_Events!$H$6:$H$20,Cash_Events!$C$6:$C$20,"FHL",Cash_Events!$B$6:$B$20,"<"&Inputs!$B$18) -> 317678.41 | D8: =B8+C8 -> 635982.48
A9: Default interest payable | B9: =SUMIFS(Daily!$H$6:$H$2400,Daily!$A$6:$A$2400,"<"&Inputs!$B$18)-SUMIFS(Cash_Events!$I$6:$I$20,Cash_Events!$C$6:$C$20,"rAGMF",Cash_Events!$B$6:$B$20,"<"&Inputs!$B$18) -> 48556.257 | C9: =SUMIFS(Daily!$M$6:$M$2400,Daily!$A$6:$A$2400,"<"&Inputs!$B$18)-SUMIFS(Cash_Events!$I$6:$I$20,Cash_Events!$C$6:$C$20,"FHL",Cash_Events!$B$6:$B$20,"<"&Inputs!$B$18) -> 48438.75 | D9: =B9+C9 -> 96995.006
A10: Total interest payable | B10: =B8+B9 -> 366860.33 | C10: =C8+C9 -> 366117.16 | D10: =B10+C10 -> 732977.49 | E10: Overdue interest incl. default
A11: Total due to lender | B11: =B7+B10 -> 1101860.3 | C11: =C7+C10 -> 1101117.2 | D11: =B11+C11 -> 2202977.5
A13: 2. Lifetime interest bridge - drawdown 09/09/2022 to reporting date
A14: USD | B14: rAGMF | C14: FHL | D14: Total | E14: Note
A15: Regular interest charged | B15: =SUMIFS(Daily!$G$6:$G$2400,Daily!$A$6:$A$2400,"<"&Inputs!$B$18) -> 494429.94 | C15: =SUMIFS(Daily!$L$6:$L$2400,Daily!$A$6:$A$2400,"<"&Inputs!$B$18) -> 493868.66 | D15: =B15+C15 -> 988298.6 | E15: 6M Term SOFR + 6.75%, ACT/ACT
A16: Default interest charged | B16: =SUMIFS(Daily!$H$6:$H$2400,Daily!$A$6:$A$2400,"<"&Inputs!$B$18) -> 57244.157 | C16: =SUMIFS(Daily!$M$6:$M$2400,Daily!$A$6:$A$2400,"<"&Inputs!$B$18) -> 56915.39 | D16: =B16+C16 -> 114159.55 | E16: 2% on outstanding principal from first missed coupon
A17: Paid by JV (coupon 1, 07/03/2023) | B17: =SUMIFS(Cash_Events!$H$6:$H$20,Cash_Events!$C$6:$C$20,"rAGMF",Cash_Events!$D$6:$D$20,"JV",Cash_Events!$B$6:$B$20,"<"&Inputs!$B$18)+SUMIFS(Cash_Events!$I$6:$I$20,Cash_Events!$C$6:$C$20,"rAGMF",Cash_Events!$D$6:$D$20,"JV",Cash_Events!$B$6:$B$20,"<"&Inputs!$B$18) -> 75648.08 | C17: =SUMIFS(Cash_Events!$H$6:$H$20,Cash_Events!$C$6:$C$20,"FHL",Cash_Events!$D$6:$D$20,"JV",Cash_Events!$B$6:$B$20,"<"&Inputs!$B$18)+SUMIFS(Cash_Events!$I$6:$I$20,Cash_Events!$C$6:$C$20,"FHL",Cash_Events!$D$6:$D$20,"JV",Cash_Events!$B$6:$B$20,"<"&Inputs!$B$18) -> 78155.75 | D17: =B17+C17 -> 153803.83 | E17: Payment vouchers PV10 / PV12
A18: Paid by 800S on JV's behalf (June 2024) | B18: =SUMIFS(Cash_Events!$H$6:$H$20,Cash_Events!$C$6:$C$20,"rAGMF",Cash_Events!$D$6:$D$20,"800S",Cash_Events!$B$6:$B$20,"<"&Inputs!$B$18)+SUMIFS(Cash_Events!$I$6:$I$20,Cash_Events!$C$6:$C$20,"rAGMF",Cash_Events!$D$6:$D$20,"800S",Cash_Events!$B$6:$B$20,"<"&Inputs!$B$18) -> 109165.69 | C18: =SUMIFS(Cash_Events!$H$6:$H$20,Cash_Events!$C$6:$C$20,"FHL",Cash_Events!$D$6:$D$20,"800S",Cash_Events!$B$6:$B$20,"<"&Inputs!$B$18)+SUMIFS(Cash_Events!$I$6:$I$20,Cash_Events!$C$6:$C$20,"FHL",Cash_Events!$D$6:$D$20,"800S",Cash_Events!$B$6:$B$20,"<"&Inputs!$B$18) -> 106511.14 | D18: =B18+C18 -> 215676.83 | E18: Incl. USD 1,163.29 cross-allocation in principal remittances
A19: Total interest charged | B19: =B15+B16 -> 551674.1 | C19: =C15+C16 -> 550784.05 | D19: =D15+D16 -> 1102458.2
A20: Total interest paid | B20: =B17+B18 -> 184813.77 | C20: =C17+C18 -> 184666.89 | D20: =D17+D18 -> 369480.66 | E20: =IF(D19=0,0,D20/D19) -> 0.33514257
A21: Interest payable (= section 1) | B21: =B19-B20 -> 366860.33 | C21: =C19-C20 -> 366117.16 | D21: =D19-D20 -> 732977.49
A22: Check vs section 1 | B22: =ROUND(B21-B10,2) -> 0 | C22: =ROUND(C21-C10,2) -> 0 | D22: =ROUND(D21-D10,2) -> 0
A24: 3. Tie-out to lender and books
A25: USD | B25: rAGMF | C25: FHL | D25: Total | E25: Note
A26: Model at 30/06/2026 | B26: =Reconciliation!B9 -> 342674.23 | C26: =Reconciliation!E9 -> 341914.87 | D26: =B26+C26 -> 684589.1
A27: Lender Overdue Interest (Amendment cl. 3.8) | B27: =Inputs!B25 -> 342674.23 | C27: =Inputs!C25 -> 341914.87 | D27: =B27+C27 -> 684589.1
A28: Variance | B28: =ROUND(B26-B27,2) -> 0 | C28: =ROUND(C26-C27,2) -> 0 | D28: =ROUND(D26-D27,2) -> 0
A29: Accrued since lender cut-off (30/06/2026 to reporting date) | B29: =B10-B26 -> 24186.096 | C29: =C10-C26 -> 24202.289 | D29: =B29+C29 -> 48388.385
A30: Interest + default payable in JV books (13/03/2026 summary) | D30: =Reconciliation!D40 -> 519656.72 | E30: Equals lender position at 09/08/2025 (not updated since)
A31: Catch-up accrual required in JV books to 30/09/2026 | D31: =Reconciliation!D45 -> 210826.52
A32: Due to 800 Super WM Pte (subrogated principal + interest) | D32: =BS_View!H62 -> 1745676.8 | E32: Ties to JV books shareholder loan
A34: 4. Lender exposure projection - 31/03/2029 (no payments)
A35: USD | B35: rAGMF | C35: FHL | D35: Total | E35: Note
A36: Interest payable - this model | B36: =Reconciliation!B20 -> 593012.8 | C36: =Reconciliation!E20 -> 592421.04 | D36: =B36+C36 -> 1185433.8
A37: Interest payable - lender guarantee calc | B37: =Inputs!B28 -> 593262.14 | C37: =Inputs!C28 -> 592670.55 | D37: =B37+C37 -> 1185932.7
A38: Variance | B38: =B36-B37 -> -249.34161 | C38: =C36-C37 -> -249.50896 | D38: =D36-D37 -> -498.85057 | E38: Lender applies /365 to leap year 2028
A39: Total exposure incl. principal - this model | B39: =INDEX(rAGMF_Monthly!$U$7:$U$85,MATCH(Inputs!$B$21,rAGMF_Monthly!$A$7:$A$85,0)) -> 1328012.8 | C39: =INDEX(FHL_Monthly!$U$7:$U$85,MATCH(Inputs!$B$21,FHL_Monthly!$A$7:$A$85,0)) -> 1327421 | D39: =B39+C39 -> 2655433.8

Sheet Year_End_Totals
A1: Year-End Totals FY2022-FY2026 - Roll-forward for Audit
A2: 800 Super GAEA (Cambodia) Co., Ltd. | USD | Lender basis, reconciled to lender exposure calc 30/06/2026 | FY = calendar year
A4: USD | B4: FY2022 | C4: FY2023 | D4: FY2024 | E4: FY2025 | F4: FY2026
A5: Period start | B5: 44813 | C5: 44927 | D5: 45292 | E5: 45658 | F5: 46023
A6: Balance date | B6: 44926 | C6: 45291 | D6: 45657 | E6: 46022 | F6: 46387
A7: Basis | B7: =IF(B6<=EOMONTH(Inputs!$B$18,-1),"Actual","Actual to "&TEXT(EOMONTH(Inputs!$B$18,-1),"dd/mm/yyyy")&" + projection") -> Actual | C7: =IF(C6<=EOMONTH(Inputs!$B$18,-1),"Actual","Actual to "&TEXT(EOMONTH(Inputs!$B$18,-1),"dd/mm/yyyy")&" + projection") -> Actual | D7: =IF(D6<=EOMONTH(Inputs!$B$18,-1),"Actual","Actual to "&TEXT(EOMONTH(Inputs!$B$18,-1),"dd/mm/yyyy")&" + projection") -> Actual | E7: =IF(E6<=EOMONTH(Inputs!$B$18,-1),"Actual","Actual to "&TEXT(EOMONTH(Inputs!$B$18,-1),"dd/mm/yyyy")&" + projection") -> Actual | F7: =IF(F6<=EOMONTH(Inputs!$B$18,-1),"Actual","Actual to "&TEXT(EOMONTH(Inputs!$B$18,-1),"dd/mm/yyyy")&" + projection") -> Actual to 30/09/2026 + projection
A9: rAGMF
A10: Principal
A11: Opening principal | B11: 0 | C11: =B14 -> 1500000 | D11: =C14 -> 1500000 | E11: =D14 -> 735000 | F11: =E14 -> 735000
A12: Drawdown | B12: =IF(AND(Inputs!B8>=B$5,Inputs!B8<=B$6),Inputs!B9,0) -> 1500000 | C12: =IF(AND(Inputs!B8>=C$5,Inputs!B8<=C$6),Inputs!B9,0) -> 0 | D12: =IF(AND(Inputs!B8>=D$5,Inputs!B8<=D$6),Inputs!B9,0) -> 0 | E12: =IF(AND(Inputs!B8>=E$5,Inputs!B8<=E$6),Inputs!B9,0) -> 0 | F12: =IF(AND(Inputs!B8>=F$5,Inputs!B8<=F$6),Inputs!B9,0) -> 0
A13: Repaid (800S guarantor payment) | B13: =-SUMIFS(Cash_Events!$G$6:$G$20,Cash_Events!$C$6:$C$20,"rAGMF",Cash_Events!$B$6:$B$20,">="&B$5,Cash_Events!$B$6:$B$20,"<="&B$6) -> 0 | C13: =-SUMIFS(Cash_Events!$G$6:$G$20,Cash_Events!$C$6:$C$20,"rAGMF",Cash_Events!$B$6:$B$20,">="&C$5,Cash_Events!$B$6:$B$20,"<="&C$6) -> 0 | D13: =-SUMIFS(Cash_Events!$G$6:$G$20,Cash_Events!$C$6:$C$20,"rAGMF",Cash_Events!$B$6:$B$20,">="&D$5,Cash_Events!$B$6:$B$20,"<="&D$6) -> -765000 | E13: =-SUMIFS(Cash_Events!$G$6:$G$20,Cash_Events!$C$6:$C$20,"rAGMF",Cash_Events!$B$6:$B$20,">="&E$5,Cash_Events!$B$6:$B$20,"<="&E$6) -> 0 | F13: =-SUMIFS(Cash_Events!$G$6:$G$20,Cash_Events!$C$6:$C$20,"rAGMF",Cash_Events!$B$6:$B$20,">="&F$5,Cash_Events!$B$6:$B$20,"<="&F$6) -> 0
A14: Closing principal | B14: =B11+B12+B13 -> 1500000 | C14: =C11+C12+C13 -> 1500000 | D14: =D11+D12+D13 -> 735000 | E14: =E11+E12+E13 -> 735000 | F14: =F11+F12+F13 -> 735000
A15: Regular interest payable
A16: Opening regular interest payable | B16: 0 | C16: =B20 -> 47227.807 | D16: =C20 -> 147229.27 | E16: =D20 -> 179232.86 | F16: =E20 -> 259725.33
A17: Interest charged (6M SOFR + 6.75%) | B17: =SUMIFS(rAGMF_Monthly!$J$7:$J$85,rAGMF_Monthly!$A$7:$A$85,">="&B$5,rAGMF_Monthly!$A$7:$A$85,"<="&B$6) -> 47227.807 | C17: =SUMIFS(rAGMF_Monthly!$J$7:$J$85,rAGMF_Monthly!$A$7:$A$85,">="&C$5,rAGMF_Monthly!$A$7:$A$85,"<="&C$6) -> 175649.55 | D17: =SUMIFS(rAGMF_Monthly!$J$7:$J$85,rAGMF_Monthly!$A$7:$A$85,">="&D$5,rAGMF_Monthly!$A$7:$A$85,"<="&D$6) -> 132481.37 | E17: =SUMIFS(rAGMF_Monthly!$J$7:$J$85,rAGMF_Monthly!$A$7:$A$85,">="&E$5,rAGMF_Monthly!$A$7:$A$85,"<="&E$6) -> 80492.478 | F17: =SUMIFS(rAGMF_Monthly!$J$7:$J$85,rAGMF_Monthly!$A$7:$A$85,">="&F$5,rAGMF_Monthly!$A$7:$A$85,"<="&F$6) -> 76767.587
A18: Paid by JV | B18: =-SUMIFS(Cash_Events!$H$6:$H$20,Cash_Events!$C$6:$C$20,"rAGMF",Cash_Events!$D$6:$D$20,"JV",Cash_Events!$B$6:$B$20,">="&B$5,Cash_Events!$B$6:$B$20,"<="&B$6) -> 0 | C18: =-SUMIFS(Cash_Events!$H$6:$H$20,Cash_Events!$C$6:$C$20,"rAGMF",Cash_Events!$D$6:$D$20,"JV",Cash_Events!$B$6:$B$20,">="&C$5,Cash_Events!$B$6:$B$20,"<="&C$6) -> -75648.08 | D18: =-SUMIFS(Cash_Events!$H$6:$H$20,Cash_Events!$C$6:$C$20,"rAGMF",Cash_Events!$D$6:$D$20,"JV",Cash_Events!$B$6:$B$20,">="&D$5,Cash_Events!$B$6:$B$20,"<="&D$6) -> 0 | E18: =-SUMIFS(Cash_Events!$H$6:$H$20,Cash_Events!$C$6:$C$20,"rAGMF",Cash_Events!$D$6:$D$20,"JV",Cash_Events!$B$6:$B$20,">="&E$5,Cash_Events!$B$6:$B$20,"<="&E$6) -> 0 | F18: =-SUMIFS(Cash_Events!$H$6:$H$20,Cash_Events!$C$6:$C$20,"rAGMF",Cash_Events!$D$6:$D$20,"JV",Cash_Events!$B$6:$B$20,">="&F$5,Cash_Events!$B$6:$B$20,"<="&F$6) -> 0
A19: Paid by 800S on JV's behalf | B19: =-SUMIFS(Cash_Events!$H$6:$H$20,Cash_Events!$C$6:$C$20,"rAGMF",Cash_Events!$D$6:$D$20,"800S",Cash_Events!$B$6:$B$20,">="&B$5,Cash_Events!$B$6:$B$20,"<="&B$6) -> 0 | C19: =-SUMIFS(Cash_Events!$H$6:$H$20,Cash_Events!$C$6:$C$20,"rAGMF",Cash_Events!$D$6:$D$20,"800S",Cash_Events!$B$6:$B$20,">="&C$5,Cash_Events!$B$6:$B$20,"<="&C$6) -> 0 | D19: =-SUMIFS(Cash_Events!$H$6:$H$20,Cash_Events!$C$6:$C$20,"rAGMF",Cash_Events!$D$6:$D$20,"800S",Cash_Events!$B$6:$B$20,">="&D$5,Cash_Events!$B$6:$B$20,"<="&D$6) -> -100477.79 | E19: =-SUMIFS(Cash_Events!$H$6:$H$20,Cash_Events!$C$6:$C$20,"rAGMF",Cash_Events!$D$6:$D$20,"800S",Cash_Events!$B$6:$B$20,">="&E$5,Cash_Events!$B$6:$B$20,"<="&E$6) -> 0 | F19: =-SUMIFS(Cash_Events!$H$6:$H$20,Cash_Events!$C$6:$C$20,"rAGMF",Cash_Events!$D$6:$D$20,"800S",Cash_Events!$B$6:$B$20,">="&F$5,Cash_Events!$B$6:$B$20,"<="&F$6) -> 0
A20: Closing regular interest payable | B20: =B16+B17+B18+B19 -> 47227.807 | C20: =C16+C17+C18+C19 -> 147229.27 | D20: =D16+D17+D18+D19 -> 179232.86 | E20: =E16+E17+E18+E19 -> 259725.33 | F20: =F16+F17+F18+F19 -> 336492.92
A21: Default interest payable
A22: Opening default interest payable | B22: 0 | C22: =B26 -> 0 | D22: =C26 -> 9123.2877 | E22: =D26 -> 22660.202 | F22: =E26 -> 37360.092
A23: Default interest charged (2% on principal) | B23: =SUMIFS(rAGMF_Monthly!$K$7:$K$85,rAGMF_Monthly!$A$7:$A$85,">="&B$5,rAGMF_Monthly!$A$7:$A$85,"<="&B$6) -> 0 | C23: =SUMIFS(rAGMF_Monthly!$K$7:$K$85,rAGMF_Monthly!$A$7:$A$85,">="&C$5,rAGMF_Monthly!$A$7:$A$85,"<="&C$6) -> 9123.2877 | D23: =SUMIFS(rAGMF_Monthly!$K$7:$K$85,rAGMF_Monthly!$A$7:$A$85,">="&D$5,rAGMF_Monthly!$A$7:$A$85,"<="&D$6) -> 22224.815 | E23: =SUMIFS(rAGMF_Monthly!$K$7:$K$85,rAGMF_Monthly!$A$7:$A$85,">="&E$5,rAGMF_Monthly!$A$7:$A$85,"<="&E$6) -> 14699.89 | F23: =SUMIFS(rAGMF_Monthly!$K$7:$K$85,rAGMF_Monthly!$A$7:$A$85,">="&F$5,rAGMF_Monthly!$A$7:$A$85,"<="&F$6) -> 14700
A24: Paid by JV | B24: =-SUMIFS(Cash_Events!$I$6:$I$20,Cash_Events!$C$6:$C$20,"rAGMF",Cash_Events!$D$6:$D$20,"JV",Cash_Events!$B$6:$B$20,">="&B$5,Cash_Events!$B$6:$B$20,"<="&B$6) -> 0 | C24: =-SUMIFS(Cash_Events!$I$6:$I$20,Cash_Events!$C$6:$C$20,"rAGMF",Cash_Events!$D$6:$D$20,"JV",Cash_Events!$B$6:$B$20,">="&C$5,Cash_Events!$B$6:$B$20,"<="&C$6) -> 0 | D24: =-SUMIFS(Cash_Events!$I$6:$I$20,Cash_Events!$C$6:$C$20,"rAGMF",Cash_Events!$D$6:$D$20,"JV",Cash_Events!$B$6:$B$20,">="&D$5,Cash_Events!$B$6:$B$20,"<="&D$6) -> 0 | E24: =-SUMIFS(Cash_Events!$I$6:$I$20,Cash_Events!$C$6:$C$20,"rAGMF",Cash_Events!$D$6:$D$20,"JV",Cash_Events!$B$6:$B$20,">="&E$5,Cash_Events!$B$6:$B$20,"<="&E$6) -> 0 | F24: =-SUMIFS(Cash_Events!$I$6:$I$20,Cash_Events!$C$6:$C$20,"rAGMF",Cash_Events!$D$6:$D$20,"JV",Cash_Events!$B$6:$B$20,">="&F$5,Cash_Events!$B$6:$B$20,"<="&F$6) -> 0
A25: Paid by 800S on JV's behalf | B25: =-SUMIFS(Cash_Events!$I$6:$I$20,Cash_Events!$C$6:$C$20,"rAGMF",Cash_Events!$D$6:$D$20,"800S",Cash_Events!$B$6:$B$20,">="&B$5,Cash_Events!$B$6:$B$20,"<="&B$6) -> 0 | C25: =-SUMIFS(Cash_Events!$I$6:$I$20,Cash_Events!$C$6:$C$20,"rAGMF",Cash_Events!$D$6:$D$20,"800S",Cash_Events!$B$6:$B$20,">="&C$5,Cash_Events!$B$6:$B$20,"<="&C$6) -> 0 | D25: =-SUMIFS(Cash_Events!$I$6:$I$20,Cash_Events!$C$6:$C$20,"rAGMF",Cash_Events!$D$6:$D$20,"800S",Cash_Events!$B$6:$B$20,">="&D$5,Cash_Events!$B$6:$B$20,"<="&D$6) -> -8687.9 | E25: =-SUMIFS(Cash_Events!$I$6:$I$20,Cash_Events!$C$6:$C$20,"rAGMF",Cash_Events!$D$6:$D$20,"800S",Cash_Events!$B$6:$B$20,">="&E$5,Cash_Events!$B$6:$B$20,"<="&E$6) -> 0 | F25: =-SUMIFS(Cash_Events!$I$6:$I$20,Cash_Events!$C$6:$C$20,"rAGMF",Cash_Events!$D$6:$D$20,"800S",Cash_Events!$B$6:$B$20,">="&F$5,Cash_Events!$B$6:$B$20,"<="&F$6) -> 0
A26: Closing default interest payable | B26: =B22+B23+B24+B25 -> 0 | C26: =C22+C23+C24+C25 -> 9123.2877 | D26: =D22+D23+D24+D25 -> 22660.202 | E26: =E22+E23+E24+E25 -> 37360.092 | F26: =F22+F23+F24+F25 -> 52060.092
A27: Year-end summary
A28: Total interest payable to lender | B28: =B20+B26 -> 47227.807 | C28: =C20+C26 -> 156352.56 | D28: =D20+D26 -> 201893.06 | E28: =E20+E26 -> 297085.43 | F28: =F20+F26 -> 388553.01
A29: Total due to lender (principal + interest) | B29: =B14+B28 -> 1547227.8 | C29: =C14+C28 -> 1656352.6 | D29: =D14+D28 -> 936893.06 | E29: =E14+E28 -> 1032085.4 | F29: =F14+F28 -> 1123553
A30: Interest expense for the year (P&L) | B30: =B17+B23 -> 47227.807 | C30: =C17+C23 -> 184772.83 | D30: =D17+D23 -> 154706.19 | E30: =E17+E23 -> 95192.368 | F30: =F17+F23 -> 91467.587
A31: Interest paid in the year (all payers) | B31: =-(B18+B19+B24+B25) -> 0 | C31: =-(C18+C19+C24+C25) -> 75648.08 | D31: =-(D18+D19+D24+D25) -> 109165.69 | E31: =-(E18+E19+E24+E25) -> 0 | F31: =-(F18+F19+F24+F25) -> 0
A32: Check: closing vs monthly schedule (=0) | B32: =ROUND(B14-INDEX(rAGMF_Monthly!$G$7:$G$85,MATCH(B$6,rAGMF_Monthly!$A$7:$A$85,0)),2)+ROUND(B20-INDEX(rAGMF_Monthly!$P$7:$P$85,MATCH(B$6,rAGMF_Monthly!$A$7:$A$85,0)),2)+ROUND(B26-INDEX(rAGMF_Monthly!$S$7:$S$85,MATCH(B$6,rAGMF_Monthly!$A$7:$A$85,0)),2) -> 0 | C32: =ROUND(C14-INDEX(rAGMF_Monthly!$G$7:$G$85,MATCH(C$6,rAGMF_Monthly!$A$7:$A$85,0)),2)+ROUND(C20-INDEX(rAGMF_Monthly!$P$7:$P$85,MATCH(C$6,rAGMF_Monthly!$A$7:$A$85,0)),2)+ROUND(C26-INDEX(rAGMF_Monthly!$S$7:$S$85,MATCH(C$6,rAGMF_Monthly!$A$7:$A$85,0)),2) -> 0 | D32: =ROUND(D14-INDEX(rAGMF_Monthly!$G$7:$G$85,MATCH(D$6,rAGMF_Monthly!$A$7:$A$85,0)),2)+ROUND(D20-INDEX(rAGMF_Monthly!$P$7:$P$85,MATCH(D$6,rAGMF_Monthly!$A$7:$A$85,0)),2)+ROUND(D26-INDEX(rAGMF_Monthly!$S$7:$S$85,MATCH(D$6,rAGMF_Monthly!$A$7:$A$85,0)),2) -> 0 | E32: =ROUND(E14-INDEX(rAGMF_Monthly!$G$7:$G$85,MATCH(E$6,rAGMF_Monthly!$A$7:$A$85,0)),2)+ROUND(E20-INDEX(rAGMF_Monthly!$P$7:$P$85,MATCH(E$6,rAGMF_Monthly!$A$7:$A$85,0)),2)+ROUND(E26-INDEX(rAGMF_Monthly!$S$7:$S$85,MATCH(E$6,rAGMF_Monthly!$A$7:$A$85,0)),2) -> 0 | F32: =ROUND(F14-INDEX(rAGMF_Monthly!$G$7:$G$85,MATCH(F$6,rAGMF_Monthly!$A$7:$A$85,0)),2)+ROUND(F20-INDEX(rAGMF_Monthly!$P$7:$P$85,MATCH(F$6,rAGMF_Monthly!$A$7:$A$85,0)),2)+ROUND(F26-INDEX(rAGMF_Monthly!$S$7:$S$85,MATCH(F$6,rAGMF_Monthly!$A$7:$A$85,0)),2) -> 0
A34: FHL
A35: Principal
A36: Opening principal | B36: 0 | C36: =B39 -> 1500000 | D36: =C39 -> 1500000 | E36: =D39 -> 735000 | F36: =E39 -> 735000
A37: Drawdown | B37: =IF(AND(Inputs!C8>=B$5,Inputs!C8<=B$6),Inputs!C9,0) -> 1500000 | C37: =IF(AND(Inputs!C8>=C$5,Inputs!C8<=C$6),Inputs!C9,0) -> 0 | D37: =IF(AND(Inputs!C8>=D$5,Inputs!C8<=D$6),Inputs!C9,0) -> 0 | E37: =IF(AND(Inputs!C8>=E$5,Inputs!C8<=E$6),Inputs!C9,0) -> 0 | F37: =IF(AND(Inputs!C8>=F$5,Inputs!C8<=F$6),Inputs!C9,0) -> 0
A38: Repaid (800S guarantor payment) | B38: =-SUMIFS(Cash_Events!$G$6:$G$20,Cash_Events!$C$6:$C$20,"FHL",Cash_Events!$B$6:$B$20,">="&B$5,Cash_Events!$B$6:$B$20,"<="&B$6) -> 0 | C38: =-SUMIFS(Cash_Events!$G$6:$G$20,Cash_Events!$C$6:$C$20,"FHL",Cash_Events!$B$6:$B$20,">="&C$5,Cash_Events!$B$6:$B$20,"<="&C$6) -> 0 | D38: =-SUMIFS(Cash_Events!$G$6:$G$20,Cash_Events!$C$6:$C$20,"FHL",Cash_Events!$B$6:$B$20,">="&D$5,Cash_Events!$B$6:$B$20,"<="&D$6) -> -765000 | E38: =-SUMIFS(Cash_Events!$G$6:$G$20,Cash_Events!$C$6:$C$20,"FHL",Cash_Events!$B$6:$B$20,">="&E$5,Cash_Events!$B$6:$B$20,"<="&E$6) -> 0 | F38: =-SUMIFS(Cash_Events!$G$6:$G$20,Cash_Events!$C$6:$C$20,"FHL",Cash_Events!$B$6:$B$20,">="&F$5,Cash_Events!$B$6:$B$20,"<="&F$6) -> 0
A39: Closing principal | B39: =B36+B37+B38 -> 1500000 | C39: =C36+C37+C38 -> 1500000 | D39: =D36+D37+D38 -> 735000 | E39: =E36+E37+E38 -> 735000 | F39: =F36+F37+F38 -> 735000
A40: Regular interest payable
A41: Opening regular interest payable | B41: 0 | C41: =B45 -> 47227.806 | D41: =C45 -> 144279.65 | E41: =D45 -> 178839 | F41: =E45 -> 259173.33
A42: Interest charged (6M SOFR + 6.75%) | B42: =SUMIFS(FHL_Monthly!$J$7:$J$85,FHL_Monthly!$A$7:$A$85,">="&B$5,FHL_Monthly!$A$7:$A$85,"<="&B$6) -> 47227.806 | C42: =SUMIFS(FHL_Monthly!$J$7:$J$85,FHL_Monthly!$A$7:$A$85,">="&C$5,FHL_Monthly!$A$7:$A$85,"<="&C$6) -> 175207.59 | D42: =SUMIFS(FHL_Monthly!$J$7:$J$85,FHL_Monthly!$A$7:$A$85,">="&D$5,FHL_Monthly!$A$7:$A$85,"<="&D$6) -> 132593.85 | E42: =SUMIFS(FHL_Monthly!$J$7:$J$85,FHL_Monthly!$A$7:$A$85,">="&E$5,FHL_Monthly!$A$7:$A$85,"<="&E$6) -> 80334.332 | F42: =SUMIFS(FHL_Monthly!$J$7:$J$85,FHL_Monthly!$A$7:$A$85,">="&F$5,FHL_Monthly!$A$7:$A$85,"<="&F$6) -> 76708.453
A43: Paid by JV | B43: =-SUMIFS(Cash_Events!$H$6:$H$20,Cash_Events!$C$6:$C$20,"FHL",Cash_Events!$D$6:$D$20,"JV",Cash_Events!$B$6:$B$20,">="&B$5,Cash_Events!$B$6:$B$20,"<="&B$6) -> 0 | C43: =-SUMIFS(Cash_Events!$H$6:$H$20,Cash_Events!$C$6:$C$20,"FHL",Cash_Events!$D$6:$D$20,"JV",Cash_Events!$B$6:$B$20,">="&C$5,Cash_Events!$B$6:$B$20,"<="&C$6) -> -78155.75 | D43: =-SUMIFS(Cash_Events!$H$6:$H$20,Cash_Events!$C$6:$C$20,"FHL",Cash_Events!$D$6:$D$20,"JV",Cash_Events!$B$6:$B$20,">="&D$5,Cash_Events!$B$6:$B$20,"<="&D$6) -> 0 | E43: =-SUMIFS(Cash_Events!$H$6:$H$20,Cash_Events!$C$6:$C$20,"FHL",Cash_Events!$D$6:$D$20,"JV",Cash_Events!$B$6:$B$20,">="&E$5,Cash_Events!$B$6:$B$20,"<="&E$6) -> 0 | F43: =-SUMIFS(Cash_Events!$H$6:$H$20,Cash_Events!$C$6:$C$20,"FHL",Cash_Events!$D$6:$D$20,"JV",Cash_Events!$B$6:$B$20,">="&F$5,Cash_Events!$B$6:$B$20,"<="&F$6) -> 0
...

Sheet Inputs
A1: Inputs & Assumptions
A2: 800 Super GAEA (Cambodia) Co., Ltd. - rAGMF and FHL loans (USD 1.5M each). Blue = hard input, black = formula, green = link, yellow = editable lever.
A4: A. Loan terms
A5: Parameter | B5: rAGMF | C5: FHL | D5: Source / note
A6: Lender | B6: responsAbility Global Micro & SME Finance Fund (M&G Luxembourg S.A.) | C6: Financing for Healthier Lives DAC | D6: Amendment Agreements (drafts 22/07/2026 rAGMF, 31/07/2026 FHL)
A7: Loan agreement date | B7: 44811 | C7: 44811 | D7: Amendment Agreements, Recital A
A8: Disbursement / interest start date | B8: 44813 | C8: 44813 | D8: Payment vouchers PV10/PV12 (07/03/2023): coupon 1 runs from 09-Sep-22
A9: Original principal | B9: 1500000 | C9: 1500000 | D9: Loan agreements; lender exposure calc Jun-26
A10: Margin over 6M Term SOFR | B10: 0.0675 | C10: 0.0675 | D10: Lender exposure calc Jun-26 (Spread)
A11: Default interest (on outstanding principal) | B11: 0.02 | C11: 0.02 | D11: Lender exposure calc Jun-26 (Penalty rate, applied to principal only, no compounding)
A12: Day count | B12: ACT/ACT | C12: ACT/ACT | D12: Lender exposure calc: /365, /366 in 2024
A13: Default interest start date (first missed coupon) | B13: 45180 | C13: 45184 | D13: Lender exposure calc Jun-26, sections 5) Penalty
A14: Net cash received at disbursement (JV books) | B14: 1485000 | C14: 1499970 | D14: JV GL 12/09/2022 (rA net of USD 15,000 approval fee; FHL net of USD 30 bank charge). Memo only
A16: B. Reporting date and scenario levers
A17: Parameter | B17: Value | D17: Source / note
A18: Reporting date (position computed for accrual days before this date) | B18: 46300 | D18: Today
A19: Lender cut-off date (Overdue Interest crystallised) | B19: 46203 | D19: Amendment Agreements cl. 3.8 / lender exposure calc 30/06/2026
A20: Default interest continues after cut-off date (1 = Yes, 0 = No) | B20: 1 | D20: 1 = no amendment effective / no cure (lender's own 2029 projection basis). Set 0 if amendment effective and default interest waived from 01/07/2026
A21: Projection end date | B21: 47208 | D21: Lender exposure calc - guarantee purpose (31/03/2029)
A23: C. Lender reference figures (used for reconciliation only, not in calculations)
A24: Item (USD) | B24: rAGMF | C24: FHL | D24: Source / note
A25: Overdue interest incl. default at 30/06/2026 | B25: 342674.23 | C25: 341914.87 | D25: Amendment Agreements cl. 3.8 (rAGMF draft 22/07/2026; FHL draft 31/07/2026)
A26: of which accrued interest at 30/06/2026 | B26: 298024.55 | C26: 297382.7 | D26: Lender exposure calc Jun-26, Summary row 6
A27: of which default interest at 30/06/2026 | B27: 44649.681 | C27: 44532.174 | D27: Lender exposure calc Jun-26, Summary row 7
A28: Projected overdue interest incl. default at 31/03/2029 | B28: 593262.14 | C28: 592670.55 | D28: Lender exposure calc - guarantee purpose, Summary row 10
A29: Lender's coupon 2 amount (settled by 800 Super) | B29: 91458.57 | C29: 90529.739 | D29: Lender exposure calc, section 1) 'Repaid by 800 Super'
A30: Lender credit applied to accrued interest (June 2024 remittances) | B30: 9019.22 | C30: 7504.76 | D30: Lender exposure calc, Summary row 6 deduction
A31: Lender credit applied to default interest (June 2024 remittances) | B31: 8687.9 | C31: 8476.64 | D31: Lender exposure calc, Summary row 7 deduction
A32: Prior model v5 checkpoint 31/03/2026 - accrued interest | B32: 278999 | C32: 278342 | D32: GAEA_Dual_Loan_2030_v5, Inputs C26:D26
A33: Prior model v5 checkpoint 31/03/2026 - default interest | B33: 40985 | C33: 40867 | D33: GAEA_Dual_Loan_2030_v5, Inputs C27:D27
A34: JV books - interest payable, both loans combined | B34: 456652.95 | D34: 800SUPERGAEA_BS_LOAN SUMMARY_CF_SG_FD_13032026, cell M12
A35: JV books - penalty payable, both loans combined | B35: 63003.77 | D35: 800SUPERGAEA_BS_LOAN SUMMARY_CF_SG_FD_13032026, cell M14
A36: JV books - shareholder loan 800 Super WM Pte | B36: 1745676.8 | D36: BS summary D24 / JV GL entry 31/10/2024 'New Shareholder Loan'
A38: D. 6M Term SOFR fixings by interest period (sorted; VLOOKUP returns the fixing in force on each accrual day)
A39: rAGMF period start | B39: 6M SOFR | C39: All-in rate | D39: Fixing / source | F39: FHL period start | G39: 6M SOFR | H39: All-in rate | I39: Fixing / source
A40: 44813 | B40: =Cash_Events!F6*365/(B9*(Cash_Events!L6-B8))-B10 -> 0.034199997 | C40: =B40+$B$10 -> 0.1017 | D40: Implied from coupon 1 voucher (USD 75,648.08, 181 days) | F40: 44813 | G40: =Cash_Events!F7*365/(C9*(Cash_Events!L7-C8))-C10 -> 0.034199996 | H40: =G40+$C$10 -> 0.1017 | I40: Implied from coupon 1 voucher (USD 78,155.75, 187 days)
A41: 44994 | B41: 0.0521501 | C41: =B41+$B$10 -> 0.1196501 | D41: T-2 07/03/2023 - lender calc | F41: 45000 | G41: 0.0522223 | H41: =G41+$C$10 -> 0.1197223 | I41: T-2 13/03/2023 - lender calc
A42: 45180 | B42: 0.0547601 | C42: =B42+$B$10 -> 0.1222601 | D42: T-2 07/09/2023 - lender calc | F42: 45184 | G42: 0.054735 | H42: =G42+$C$10 -> 0.122235 | I42: T-2 13/09/2023 - lender calc
A43: 45362 | B43: 0.0523565 | C43: =B43+$B$10 -> 0.1198565 | D43: T-2 07/03/2024 - lender calc | F43: 45366 | G43: 0.0525075 | H43: =G43+$C$10 -> 0.1200075 | I43: T-2 13/03/2024 - lender calc
A44: 45544 | B44: 0.0461541 | C44: =B44+$B$10 -> 0.1136541 | D44: T-2 05/09/2024 - lender calc | F44: 45551 | G44: 0.0457048 | H44: =G44+$C$10 -> 0.1132048 | I44: T-2 12/09/2024 - lender calc
...

Sheet Cash_Events
A1: Cash Events & Lender Allocation
A2: All cash paid to the lenders since drawdown. Allocation per lender exposure calc Jun-26. Add any new payment in the yellow rows (allocation: enter principal and default portions; regular interest = balance).
A3: Entry format: Loan = rAGMF or FHL; Payer = JV or 800S. Example: 15/09/2026 | rAGMF | JV | Amendment instalment | 16,000.00 | 0.00 | (auto) | 0.00
A5: # | B5: Value date | C5: Loan | D5: Payer | E5: Description | F5: Cash amount (USD) | G5: Principal | H5: Regular interest | I5: Default interest | J5: Check | K5: Bank ref / source | L5: Accrual cover end | M5: Month bucket
A6: 1 | B6: 44992 | C6: rAGMF | D6: JV | E6: Coupon 1 (09/09/2022-09/03/2023) | F6: 75648.08 | G6: 0 | H6: =F6-G6-I6 -> 75648.08 | I6: 0 | J6: =ROUND(F6-G6-H6-I6,2) -> 0 | K6: PV #10, 07-Mar-23, bank transfer USD | L6: 44994 | M6: =IF(B6="","",EOMONTH(B6,0)) -> 45016
A7: 2 | B7: 44992 | C7: FHL | D7: JV | E7: Coupon 1 (09/09/2022-15/03/2023) | F7: 78155.75 | G7: 0 | H7: =F7-G7-I7 -> 78155.75 | I7: 0 | J7: =ROUND(F7-G7-H7-I7,2) -> 0 | K7: PV #12, 07-Mar-23, bank transfer USD | L7: 45000 | M7: =IF(B7="","",EOMONTH(B7,0)) -> 45016
A8: 3 | B8: 45456 | C8: rAGMF | D8: 800S | E8: Accrued and defaulted interest payment (800 Super WM Pte, OCBC SGD a/c) | F8: 108002.4 | G8: 0 | H8: =F8-G8-I8 -> 99314.5 | I8: =Inputs!B31 -> 8687.9 | J8: =ROUND(F8-G8-H8-I8,2) -> 0 | K8: OCBC TT created 12/06/2024, value 13/06/2024 | M8: =IF(B8="","",EOMONTH(B8,0)) -> 45473
A9: 4 | B9: 45456 | C9: FHL | D9: 800S | E9: Accrued and defaulted interest payment (800 Super WM Pte, OCBC SGD a/c) | F9: 107674.43 | G9: 0 | H9: =F9-G9-I9 -> 99197.79 | I9: =Inputs!C31 -> 8476.64 | J9: =ROUND(F9-G9-H9-I9,2) -> 0 | K9: OCBC TT created 12/06/2024, value 13/06/2024 | M9: =IF(B9="","",EOMONTH(B9,0)) -> 45473
A10: 5 | B10: 45471 | C10: rAGMF | D10: 800S | E10: Principal repayment 51% (guarantor payment); USD 1,163.29 above USD 765,000 applied to interest | F10: 766163.29 | G10: 765000 | H10: =F10-G10-I10 -> 1163.29 | I10: 0 | J10: =ROUND(F10-G10-H10-I10,2) -> 0 | K10: UOB FT24060327092395, value 28/06/2024 | M10: =IF(B10="","",EOMONTH(B10,0)) -> 45473
A11: 6 | B11: 45471 | C11: FHL | D11: 800S | E11: Principal repayment 51% (guarantor payment); USD 1,163.29 shortfall vs USD 765,000 met from interest remittance | F11: 763836.71 | G11: 765000 | H11: =F11-G11-I11 -> -1163.29 | I11: 0 | J11: =ROUND(F11-G11-H11-I11,2) -> 0 | K11: UOB FT24060327079586, value 28/06/2024 | M11: =IF(B11="","",EOMONTH(B11,0)) -> 45473
A12: 7 | H12: =IF(F12="",0,F12-G12-I12) -> 0 | J12: =IF(F12="",0,ROUND(F12-G12-H12-I12,2)) -> 0 | M12: =IF(B12="","",EOMONTH(B12,0))
A13: 8 | H13: =IF(F13="",0,F13-G13-I13) -> 0 | J13: =IF(F13="",0,ROUND(F13-G13-H13-I13,2)) -> 0 | M13: =IF(B13="","",EOMONTH(B13,0))
A14: 9 | H14: =IF(F14="",0,F14-G14-I14) -> 0 | J14: =IF(F14="",0,ROUND(F14-G14-H14-I14,2)) -> 0 | M14: =IF(B14="","",EOMONTH(B14,0))
A15: 10 | H15: =IF(F15="",0,F15-G15-I15) -> 0 | J15: =IF(F15="",0,ROUND(F15-G15-H15-I15,2)) -> 0 | M15: =IF(B15="","",EOMONTH(B15,0))
A16: 11 | H16: =IF(F16="",0,F16-G16-I16) -> 0 | J16: =IF(F16="",0,ROUND(F16-G16-H16-I16,2)) -> 0 | M16: =IF(B16="","",EOMONTH(B16,0))
A17: 12 | H17: =IF(F17="",0,F17-G17-I17) -> 0 | J17: =IF(F17="",0,ROUND(F17-G17-H17-I17,2)) -> 0 | M17: =IF(B17="","",EOMONTH(B17,0))
A18: 13 | H18: =IF(F18="",0,F18-G18-I18) -> 0 | J18: =IF(F18="",0,ROUND(F18-G18-H18-I18,2)) -> 0 | M18: =IF(B18="","",EOMONTH(B18,0))
A19: 14 | H19: =IF(F19="",0,F19-G19-I19) -> 0 | J19: =IF(F19="",0,ROUND(F19-G19-H19-I19,2)) -> 0 | M19: =IF(B19="","",EOMONTH(B19,0))
A20: 15 | H20: =IF(F20="",0,F20-G20-I20) -> 0 | J20: =IF(F20="",0,ROUND(F20-G20-H20-I20,2)) -> 0 | M20: =IF(B20="","",EOMONTH(B20,0))
A22: Total | F22: =SUM(F6:F20) -> 1899480.7 | G22: =SUM(G6:G20) -> 1530000 | H22: =SUM(H6:H20) -> 352316.12 | I22: =SUM(I6:I20) -> 17164.54 | J22: =SUM(J6:J20) -> 0
A24: Summary by payer
B25: Payer | C25: Loan | F25: Cash | G25: Principal | H25: Regular interest | I25: Default interest | J25: Interest total
B26: JV | C26: rAGMF | F26: =SUMIFS(F$6:F$20,$D$6:$D$20,$B26,$C$6:$C$20,$C26) -> 75648.08 | G26: =SUMIFS(G$6:G$20,$D$6:$D$20,$B26,$C$6:$C$20,$C26) -> 0 | H26: =SUMIFS(H$6:H$20,$D$6:$D$20,$B26,$C$6:$C$20,$C26) -> 75648.08 | I26: =SUMIFS(I$6:I$20,$D$6:$D$20,$B26,$C$6:$C$20,$C26) -> 0 | J26: =H26+I26 -> 75648.08
B27: JV | C27: FHL | F27: =SUMIFS(F$6:F$20,$D$6:$D$20,$B27,$C$6:$C$20,$C27) -> 78155.75 | G27: =SUMIFS(G$6:G$20,$D$6:$D$20,$B27,$C$6:$C$20,$C27) -> 0 | H27: =SUMIFS(H$6:H$20,$D$6:$D$20,$B27,$C$6:$C$20,$C27) -> 78155.75 | I27: =SUMIFS(I$6:I$20,$D$6:$D$20,$B27,$C$6:$C$20,$C27) -> 0 | J27: =H27+I27 -> 78155.75
B28: 800S | C28: rAGMF | F28: =SUMIFS(F$6:F$20,$D$6:$D$20,$B28,$C$6:$C$20,$C28) -> 874165.69 | G28: =SUMIFS(G$6:G$20,$D$6:$D$20,$B28,$C$6:$C$20,$C28) -> 765000 | H28: =SUMIFS(H$6:H$20,$D$6:$D$20,$B28,$C$6:$C$20,$C28) -> 100477.79 | I28: =SUMIFS(I$6:I$20,$D$6:$D$20,$B28,$C$6:$C$20,$C28) -> 8687.9 | J28: =H28+I28 -> 109165.69
B29: 800S | C29: FHL | F29: =SUMIFS(F$6:F$20,$D$6:$D$20,$B29,$C$6:$C$20,$C29) -> 871511.14 | G29: =SUMIFS(G$6:G$20,$D$6:$D$20,$B29,$C$6:$C$20,$C29) -> 765000 | H29: =SUMIFS(H$6:H$20,$D$6:$D$20,$B29,$C$6:$C$20,$C29) -> 98034.5 | I29: =SUMIFS(I$6:I$20,$D$6:$D$20,$B29,$C$6:$C$20,$C29) -> 8476.64 | J29: =H29+I29 -> 106511.14
B30: Total | F30: =SUM(F26:F29) -> 1899480.7 | G30: =SUM(G26:G29) -> 1530000 | H30: =SUM(H26:H29) -> 352316.12 | I30: =SUM(I26:I29) -> 17164.54 | J30: =SUM(J26:J29) -> 369480.66

Sheet Daily
A1: Daily Accrual Engine
A2: One row per accrual day (interest for day d accrues from d to d+1). Month bucket = month-end boundary convention used by the lender (e.g. 'to 30/06/2026' excludes 30 June).
A5: Accrual day | B5: Month bucket | C5: Year basis | D5: rAGMF principal | E5: rAGMF 6M SOFR | F5: rAGMF all-in | G5: rAGMF regular interest | H5: rAGMF default interest | I5: FHL principal | J5: FHL 6M SOFR | K5: FHL all-in | L5: FHL regular interest | M5: FHL default interest
A6: =Inputs!B8 -> 44813 | B6: =EOMONTH(A6+1,0) -> 44834 | C6: =IF(MOD(YEAR(A6),4)=0,366,365) -> 365 | D6: =Inputs!$B$9-SUMIFS(Cash_Events!$G$6:$G$20,Cash_Events!$C$6:$C$20,"rAGMF",Cash_Events!$B$6:$B$20,"<="&A6) -> 1500000 | E6: =VLOOKUP(A6,Inputs!$A$40:$B$48,2,TRUE()) -> 0.034199997 | F6: =E6+Inputs!$B$10 -> 0.1017 | G6: =D6*F6/C6 -> 417.94519 | H6: =IF(AND(A6>=Inputs!$B$13,OR(A6<Inputs!$B$19,Inputs!$B$20=1)),D6*Inputs!$B$11/C6,0) -> 0 | I6: =Inputs!$C$9-SUMIFS(Cash_Events!$G$6:$G$20,Cash_Events!$C$6:$C$20,"FHL",Cash_Events!$B$6:$B$20,"<="&A6) -> 1500000 | J6: =VLOOKUP(A6,Inputs!$F$40:$G$48,2,TRUE()) -> 0.034199996 | K6: =J6+Inputs!$C$10 -> 0.1017 | L6: =I6*K6/C6 -> 417.94519 | M6: =IF(AND(A6>=Inputs!$C$13,OR(A6<Inputs!$B$19,Inputs!$B$20=1)),I6*Inputs!$C$11/C6,0) -> 0
A7: =A6+1 -> 44814 | B7: =EOMONTH(A7+1,0) -> 44834 | C7: =IF(MOD(YEAR(A7),4)=0,366,365) -> 365 | D7: =Inputs!$B$9-SUMIFS(Cash_Events!$G$6:$G$20,Cash_Events!$C$6:$C$20,"rAGMF",Cash_Events!$B$6:$B$20,"<="&A7) -> 1500000 | E7: =VLOOKUP(A7,Inputs!$A$40:$B$48,2,TRUE()) -> 0.034199997 | F7: =E7+Inputs!$B$10 -> 0.1017 | G7: =D7*F7/C7 -> 417.94519 | H7: =IF(AND(A7>=Inputs!$B$13,OR(A7<Inputs!$B$19,Inputs!$B$20=1)),D7*Inputs!$B$11/C7,0) -> 0 | I7: =Inputs!$C$9-SUMIFS(Cash_Events!$G$6:$G$20,Cash_Events!$C$6:$C$20,"FHL",Cash_Events!$B$6:$B$20,"<="&A7) -> 1500000 | J7: =VLOOKUP(A7,Inputs!$F$40:$G$48,2,TRUE()) -> 0.034199996 | K7: =J7+Inputs!$C$10 -> 0.1017 | L7: =I7*K7/C7 -> 417.94519 | M7: =IF(AND(A7>=Inputs!$C$13,OR(A7<Inputs!$B$19,Inputs!$B$20=1)),I7*Inputs!$C$11/C7,0) -> 0
A8: =A7+1 -> 44815 | B8: =EOMONTH(A8+1,0) -> 44834 | C8: =IF(MOD(YEAR(A8),4)=0,366,365) -> 365 | D8: =Inputs!$B$9-SUMIFS(Cash_Events!$G$6:$G$20,Cash_Events!$C$6:$C$20,"rAGMF",Cash_Events!$B$6:$B$20,"<="&A8) -> 1500000 | E8: =VLOOKUP(A8,Inputs!$A$40:$B$48,2,TRUE()) -> 0.034199997 | F8: =E8+Inputs!$B$10 -> 0.1017 | G8: =D8*F8/C8 -> 417.94519 | H8: =IF(AND(A8>=Inputs!$B$13,OR(A8<Inputs!$B$19,Inputs!$B$20=1)),D8*Inputs!$B$11/C8,0) -> 0 | I8: =Inputs!$C$9-SUMIFS(Cash_Events!$G$6:$G$20,Cash_Events!$C$6:$C$20,"FHL",Cash_Events!$B$6:$B$20,"<="&A8) -> 1500000 | J8: =VLOOKUP(A8,Inputs!$F$40:$G$48,2,TRUE()) -> 0.034199996 | K8: =J8+Inputs!$C$10 -> 0.1017 | L8: =I8*K8/C8 -> 417.94519 | M8: =IF(AND(A8>=Inputs!$C$13,OR(A8<Inputs!$B$19,Inputs!$B$20=1)),I8*Inputs!$C$11/C8,0) -> 0
A9: =A8+1 -> 44816 | B9: =EOMONTH(A9+1,0) -> 44834 | C9: =IF(MOD(YEAR(A9),4)=0,366,365) -> 365 | D9: =Inputs!$B$9-SUMIFS(Cash_Events!$G$6:$G$20,Cash_Events!$C$6:$C$20,"rAGMF",Cash_Events!$B$6:$B$20,"<="&A9) -> 1500000 | E9: =VLOOKUP(A9,Inputs!$A$40:$B$48,2,TRUE()) -> 0.034199997 | F9: =E9+Inputs!$B$10 -> 0.1017 | G9: =D9*F9/C9 -> 417.94519 | H9: =IF(AND(A9>=Inputs!$B$13,OR(A9<Inputs!$B$19,Inputs!$B$20=1)),D9*Inputs!$B$11/C9,0) -> 0 | I9: =Inputs!$C$9-SUMIFS(Cash_Events!$G$6:$G$20,Cash_Events!$C$6:$C$20,"FHL",Cash_Events!$B$6:$B$20,"<="&A9) -> 1500000 | J9: =VLOOKUP(A9,Inputs!$F$40:$G$48,2,TRUE()) -> 0.034199996 | K9: =J9+Inputs!$C$10 -> 0.1017 | L9: =I9*K9/C9 -> 417.94519 | M9: =IF(AND(A9>=Inputs!$C$13,OR(A9<Inputs!$B$19,Inputs!$B$20=1)),I9*Inputs!$C$11/C9,0) -> 0
A10: =A9+1 -> 44817 | B10: =EOMONTH(A10+1,0) -> 44834 | C10: =IF(MOD(YEAR(A10),4)=0,366,365) -> 365 | D10: =Inputs!$B$9-SUMIFS(Cash_Events!$G$6:$G$20,Cash_Events!$C$6:$C$20,"rAGMF",Cash_Events!$B$6:$B$20,"<="&A10) -> 1500000 | E10: =VLOOKUP(A10,Inputs!$A$40:$B$48,2,TRUE()) -> 0.034199997 | F10: =E10+Inputs!$B$10 -> 0.1017 | G10: =D10*F10/C10 -> 417.94519 | H10: =IF(AND(A10>=Inputs!$B$13,OR(A10<Inputs!$B$19,Inputs!$B$20=1)),D10*Inputs!$B$11/C10,0) -> 0 | I10: =Inputs!$C$9-SUMIFS(Cash_Events!$G$6:$G$20,Cash_Events!$C$6:$C$20,"FHL",Cash_Events!$B$6:$B$20,"<="&A10) -> 1500000 | J10: =VLOOKUP(A10,Inputs!$F$40:$G$48,2,TRUE()) -> 0.034199996 | K10: =J10+Inputs!$C$10 -> 0.1017 | L10: =I10*K10/C10 -> 417.94519 | M10: =IF(AND(A10>=Inputs!$C$13,OR(A10<Inputs!$B$19,Inputs!$B$20=1)),I10*Inputs!$C$11/C10,0) -> 0
A11: =A10+1 -> 44818 | B11: =EOMONTH(A11+1,0) -> 44834 | C11: =IF(MOD(YEAR(A11),4)=0,366,365) -> 365 | D11: =Inputs!$B$9-SUMIFS(Cash_Events!$G$6:$G$20,Cash_Events!$C$6:$C$20,"rAGMF",Cash_Events!$B$6:$B$20,"<="&A11) -> 1500000 | E11: =VLOOKUP(A11,Inputs!$A$40:$B$48,2,TRUE()) -> 0.034199997 | F11: =E11+Inputs!$B$10 -> 0.1017 | G11: =D11*F11/C11 -> 417.94519 | H11: =IF(AND(A11>=Inputs!$B$13,OR(A11<Inputs!$B$19,Inputs!$B$20=1)),D11*Inputs!$B$11/C11,0) -> 0 | I11: =Inputs!$C$9-SUMIFS(Cash_Events!$G$6:$G$20,Cash_Events!$C$6:$C$20,"FHL",Cash_Events!$B$6:$B$20,"<="&A11) -> 1500000 | J11: =VLOOKUP(A11,Inputs!$F$40:$G$48,2,TRUE()) -> 0.034199996 | K11: =J11+Inputs!$C$10 -> 0.1017 | L11: =I11*K11/C11 -> 417.94519 | M11: =IF(AND(A11>=Inputs!$C$13,OR(A11<Inputs!$B$19,Inputs!$B$20=1)),I11*Inputs!$C$11/C11,0) -> 0
A12: =A11+1 -> 44819 | B12: =EOMONTH(A12+1,0) -> 44834 | C12: =IF(MOD(YEAR(A12),4)=0,366,365) -> 365 | D12: =Inputs!$B$9-SUMIFS(Cash_Events!$G$6:$G$20,Cash_Events!$C$6:$C$20,"rAGMF",Cash_Events!$B$6:$B$20,"<="&A12) -> 1500000 | E12: =VLOOKUP(A12,Inputs!$A$40:$B$48,2,TRUE()) -> 0.034199997 | F12: =E12+Inputs!$B$10 -> 0.1017 | G12: =D12*F12/C12 -> 417.94519 | H12: =IF(AND(A12>=Inputs!$B$13,OR(A12<Inputs!$B$19,Inputs!$B$20=1)),D12*Inputs!$B$11/C12,0) -> 0 | I12: =Inputs!$C$9-SUMIFS(Cash_Events!$G$6:$G$20,Cash_Events!$C$6:$C$20,"FHL",Cash_Events!$B$6:$B$20,"<="&A12) -> 1500000 | J12: =VLOOKUP(A12,Inputs!$F$40:$G$48,2,TRUE()) -> 0.034199996 | K12: =J12+Inputs!$C$10 -> 0.1017 | L12: =I12*K12/C12 -> 417.94519 | M12: =IF(AND(A12>=Inputs!$C$13,OR(A12<Inputs!$B$19,Inputs!$B$20=1)),I12*Inputs!$C$11/C12,0) -> 0
A13: =A12+1 -> 44820 | B13: =EOMONTH(A13+1,0) -> 44834 | C13: =IF(MOD(YEAR(A13),4)=0,366,365) -> 365 | D13: =Inputs!$B$9-SUMIFS(Cash_Events!$G$6:$G$20,Cash_Events!$C$6:$C$20,"rAGMF",Cash_Events!$B$6:$B$20,"<="&A13) -> 1500000 | E13: =VLOOKUP(A13,Inputs!$A$40:$B$48,2,TRUE()) -> 0.034199997 | F13: =E13+Inputs!$B$10 -> 0.1017 | G13: =D13*F13/C13 -> 417.94519 | H13: =IF(AND(A13>=Inputs!$B$13,OR(A13<Inputs!$B$19,Inputs!$B$20=1)),D13*Inputs!$B$11/C13,0) -> 0 | I13: =Inputs!$C$9-SUMIFS(Cash_Events!$G$6:$G$20,Cash_Events!$C$6:$C$20,"FHL",Cash_Events!$B$6:$B$20,"<="&A13) -> 1500000 | J13: =VLOOKUP(A13,Inputs!$F$40:$G$48,2,TRUE()) -> 0.034199996 | K13: =J13+Inputs!$C$10 -> 0.1017 | L13: =I13*K13/C13 -> 417.94519 | M13: =IF(AND(A13>=Inputs!$C$13,OR(A13<Inputs!$B$19,Inputs!$B$20=1)),I13*Inputs!$C$11/C13,0) -> 0
A14: =A13+1 -> 44821 | B14: =EOMONTH(A14+1,0) -> 44834 | C14: =IF(MOD(YEAR(A14),4)=0,366,365) -> 365 | D14: =Inputs!$B$9-SUMIFS(Cash_Events!$G$6:$G$20,Cash_Events!$C$6:$C$20,"rAGMF",Cash_Events!$B$6:$B$20,"<="&A14) -> 1500000 | E14: =VLOOKUP(A14,Inputs!$A$40:$B$48,2,TRUE()) -> 0.034199997 | F14: =E14+Inputs!$B$10 -> 0.1017 | G14: =D14*F14/C14 -> 417.94519 | H14: =IF(AND(A14>=Inputs!$B$13,OR(A14<Inputs!$B$19,Inputs!$B$20=1)),D14*Inputs!$B$11/C14,0) -> 0 | I14: =Inputs!$C$9-SUMIFS(Cash_Events!$G$6:$G$20,Cash_Events!$C$6:$C$20,"FHL",Cash_Events!$B$6:$B$20,"<="&A14) -> 1500000 | J14: =VLOOKUP(A14,Inputs!$F$40:$G$48,2,TRUE()) -> 0.034199996 | K14: =J14+Inputs!$C$10 -> 0.1017 | L14: =I14*K14/C14 -> 417.94519 | M14: =IF(AND(A14>=Inputs!$C$13,OR(A14<Inputs!$B$19,Inputs!$B$20=1)),I14*Inputs!$C$11/C14,0) -> 0
A15: =A14+1 -> 44822 | B15: =EOMONTH(A15+1,0) -> 44834 | C15: =IF(MOD(YEAR(A15),4)=0,366,365) -> 365 | D15: =Inputs!$B$9-SUMIFS(Cash_Events!$G$6:$G$20,Cash_Events!$C$6:$C$20,"rAGMF",Cash_Events!$B$6:$B$20,"<="&A15) -> 1500000 | E15: =VLOOKUP(A15,Inputs!$A$40:$B$48,2,TRUE()) -> 0.034199997 | F15: =E15+Inputs!$B$10 -> 0.1017 | G15: =D15*F15/C15 -> 417.94519 | H15: =IF(AND(A15>=Inputs!$B$13,OR(A15<Inputs!$B$19,Inputs!$B$20=1)),D15*Inputs!$B$11/C15,0) -> 0 | I15: =Inputs!$C$9-SUMIFS(Cash_Events!$G$6:$G$20,Cash_Events!$C$6:$C$20,"FHL",Cash_Events!$B$6:$B$20,"<="&A15) -> 1500000 | J15: =VLOOKUP(A15,Inputs!$F$40:$G$48,2,TRUE()) -> 0.034199996 | K15: =J15+Inputs!$C$10 -> 0.1017 | L15: =I15*K15/C15 -> 417.94519 | M15: =IF(AND(A15>=Inputs!$C$13,OR(A15<Inputs!$B$19,Inputs!$B$20=1)),I15*Inputs!$C$11/C15,0) -> 0
A16: =A15+1 -> 44823 | B16: =EOMONTH(A16+1,0) -> 44834 | C16: =IF(MOD(YEAR(A16),4)=0,366,365) -> 365 | D16: =Inputs!$B$9-SUMIFS(Cash_Events!$G$6:$G$20,Cash_Events!$C$6:$C$20,"rAGMF",Cash_Events!$B$6:$B$20,"<="&A16) -> 1500000 | E16: =VLOOKUP(A16,Inputs!$A$40:$B$48,2,TRUE()) -> 0.034199997 | F16: =E16+Inputs!$B$10 -> 0.1017 | G16: =D16*F16/C16 -> 417.94519 | H16: =IF(AND(A16>=Inputs!$B$13,OR(A16<Inputs!$B$19,Inputs!$B$20=1)),D16*Inputs!$B$11/C16,0) -> 0 | I16: =Inputs!$C$9-SUMIFS(Cash_Events!$G$6:$G$20,Cash_Events!$C$6:$C$20,"FHL",Cash_Events!$B$6:$B$20,"<="&A16) -> 1500000 | J16: =VLOOKUP(A16,Inputs!$F$40:$G$48,2,TRUE()) -> 0.034199996 | K16: =J16+Inputs!$C$10 -> 0.1017 | L16: =I16*K16/C16 -> 417.94519 | M16: =IF(AND(A16>=Inputs!$C$13,OR(A16<Inputs!$B$19,Inputs!$B$20=1)),I16*Inputs!$C$11/C16,0) -> 0
A17: =A16+1 -> 44824 | B17: =EOMONTH(A17+1,0) -> 44834 | C17: =IF(MOD(YEAR(A17),4)=0,366,365) -> 365 | D17: =Inputs!$B$9-SUMIFS(Cash_Events!$G$6:$G$20,Cash_Events!$C$6:$C$20,"rAGMF",Cash_Events!$B$6:$B$20,"<="&A17) -> 1500000 | E17: =VLOOKUP(A17,Inputs!$A$40:$B$48,2,TRUE()) -> 0.034199997 | F17: =E17+Inputs!$B$10 -> 0.1017 | G17: =D17*F17/C17 -> 417.94519 | H17: =IF(AND(A17>=Inputs!$B$13,OR(A17<Inputs!$B$19,Inputs!$B$20=1)),D17*Inputs!$B$11/C17,0) -> 0 | I17: =Inputs!$C$9-SUMIFS(Cash_Events!$G$6:$G$20,Cash_Events!$C$6:$C$20,"FHL",Cash_Events!$B$6:$B$20,"<="&A17) -> 1500000 | J17: =VLOOKUP(A17,Inputs!$F$40:$G$48,2,TRUE()) -> 0.034199996 | K17: =J17+Inputs!$C$10 -> 0.1017 | L17: =I17*K17/C17 -> 417.94519 | M17: =IF(AND(A17>=Inputs!$C$13,OR(A17<Inputs!$B$19,Inputs!$B$20=1)),I17*Inputs!$C$11/C17,0) -> 0
A18: =A17+1 -> 44825 | B18: =EOMONTH(A18+1,0) -> 44834 | C18: =IF(MOD(YEAR(A18),4)=0,366,365) -> 365 | D18: =Inputs!$B$9-SUMIFS(Cash_Events!$G$6:$G$20,Cash_Events!$C$6:$C$20,"rAGMF",Cash_Events!$B$6:$B$20,"<="&A18) -> 1500000 | E18: =VLOOKUP(A18,Inputs!$A$40:$B$48,2,TRUE()) -> 0.034199997 | F18: =E18+Inputs!$B$10 -> 0.1017 | G18: =D18*F18/C18 -> 417.94519 | H18: =IF(AND(A18>=Inputs!$B$13,OR(A18<Inputs!$B$19,Inputs!$B$20=1)),D18*Inputs!$B$11/C18,0) -> 0 | I18: =Inputs!$C$9-SUMIFS(Cash_Events!$G$6:$G$20,Cash_Events!$C$6:$C$20,"FHL",Cash_Events!$B$6:$B$20,"<="&A18) -> 1500000 | J18: =VLOOKUP(A18,Inputs!$F$40:$G$48,2,TRUE()) -> 0.034199996 | K18: =J18+Inputs!$C$10 -> 0.1017 | L18: =I18*K18/C18 -> 417.94519 | M18: =IF(AND(A18>=Inputs!$C$13,OR(A18<Inputs!$B$19,Inputs!$B$20=1)),I18*Inputs!$C$11/C18,0) -> 0
... A2400: =A2399+1 -> 47207 | B2400: =EOMONTH(A2400+1,0) -> 47208 | C2400: =IF(MOD(YEAR(A2400),4)=0,366,365) -> 365 | D2400: =Inputs!$B$9-SUMIFS(Cash_Events!$G$6:$G$20,Cash_Events!$C$6:$C$20,"rAGMF",Cash_Events!$B$6:$B$20,"<="&A2400) -> 735000 | E2400: =VLOOKUP(A2400,Inputs!$A$40:$B$48,2,TRUE()) -> 0.0363225 | F2400: =E2400+Inputs!$B$10 -> 0.1038225 | G2400: =D2400*F2400/C2400 -> 209.06723 | H2400: =IF(AND(A2400>=Inputs!$B$13,OR(A2400<Inputs!$B$19,Inputs!$B$20=1)),D2400*Inputs!$B$11/C2400,0) -> 40.273973 | I2400: =Inputs!$C$9-SUMIFS(Cash_Events!$G$6:$G$20,Cash_Events!$C$6:$C$20,"FHL",Cash_Events!$B$6:$B$20,"<="&A2400) -> 735000 | J2400: =VLOOKUP(A2400,Inputs!$F$40:$G$48,2,TRUE()) -> 0.0364054 | K2400: =J2400+Inputs!$C$10 -> 0.1039054 | L2400: =I2400*K2400/C2400 -> 209.23416 | M2400: =IF(AND(A2400>=Inputs!$C$13,OR(A2400<Inputs!$B$19,Inputs!$B$20=1)),I2400*Inputs!$C$11/C2400,0) -> 40.273973

Sheet rAGMF_Monthly
A1: rAGMF - Monthly Loan Life (drawdown 09/09/2022 to 31/03/2029)
A2: Actual = reconstructed to last month-end before reporting date; Projection = no further payments, lender method. Interest payable = lender's view of overdue amounts.
A4: Lender: | B4: =Inputs!B6 -> responsAbility Global Micro & SME Finance Fund (M&G Luxembourg S.A.)
A5: Shaded rows = projection. Blue band = lender cut-off 30/06/2026.
A6: Month end | B6: Accrual from | C6: Days | D6: Status | E6: Opening principal | F6: Principal repaid | G6: Closing principal | H6: 6M SOFR (period end) | I6: All-in rate | J6: Regular interest accrued | K6: Default interest accrued | L6: Total interest charge | M6: Opening regular interest payable | N6: Regular paid by JV | O6: Regular paid by 800S | P6: Closing regular interest payable | Q6: Opening default payable | R6: Default paid | S6: Closing default payable | T6: TOTAL INTEREST PAYABLE | U6: TOTAL EXPOSURE (principal + interest) | V6: Cumulative interest charged | W6: Cumulative interest paid | X6: Check (=0) | Y6: Events
A7: 44834 | B7: =Inputs!B8 -> 44813 | C7: =A7-B7 -> 21 | D7: =IF(A7<=EOMONTH(Inputs!$B$18,-1),"Actual","Projection") -> Actual | E7: =Inputs!B9 -> 1500000 | F7: =SUMIFS(Cash_Events!$G$6:$G$20,Cash_Events!$C$6:$C$20,"rAGMF",Cash_Events!$M$6:$M$20,A7) -> 0 | G7: =E7-F7 -> 1500000 | H7: =VLOOKUP(A7-1,Inputs!$A$40:$B$48,2,TRUE()) -> 0.034199997 | I7: =H7+Inputs!B10 -> 0.1017 | J7: =SUMIFS(Daily!$G$6:$G$2400,Daily!$B$6:$B$2400,A7) -> 8776.8491 | K7: =SUMIFS(Daily!$H$6:$H$2400,Daily!$B$6:$B$2400,A7) -> 0 | L7: =J7+K7 -> 8776.8491 | M7: 0 | N7: =SUMIFS(Cash_Events!$H$6:$H$20,Cash_Events!$C$6:$C$20,"rAGMF",Cash_Events!$D$6:$D$20,"JV",Cash_Events!$M$6:$M$20,A7) -> 0 | O7: =SUMIFS(Cash_Events!$H$6:$H$20,Cash_Events!$C$6:$C$20,"rAGMF",Cash_Events!$D$6:$D$20,"800S",Cash_Events!$M$6:$M$20,A7) -> 0 | P7: =M7+J7-N7-O7 -> 8776.8491 | Q7: 0 | R7: =SUMIFS(Cash_Events!$I$6:$I$20,Cash_Events!$C$6:$C$20,"rAGMF",Cash_Events!$M$6:$M$20,A7) -> 0 | S7: =Q7+K7-R7 -> 0 | T7: =P7+S7 -> 8776.8491 | U7: =G7+T7 -> 1508776.8 | V7: =L7 -> 8776.8491 | W7: =N7+O7+R7 -> 0 | X7: =ROUND(V7-W7-T7,2) -> 0 | Y7: Drawdown 09/09/2022
A8: =EOMONTH(A7,1) -> 44865 | B8: =A7 -> 44834 | C8: =A8-B8 -> 31 | D8: =IF(A8<=EOMONTH(Inputs!$B$18,-1),"Actual","Projection") -> Actual | E8: =G7 -> 1500000 | F8: =SUMIFS(Cash_Events!$G$6:$G$20,Cash_Events!$C$6:$C$20,"rAGMF",Cash_Events!$M$6:$M$20,A8) -> 0 | G8: =E8-F8 -> 1500000 | H8: =VLOOKUP(A8-1,Inputs!$A$40:$B$48,2,TRUE()) -> 0.034199997 | I8: =H8+Inputs!B10 -> 0.1017 | J8: =SUMIFS(Daily!$G$6:$G$2400,Daily!$B$6:$B$2400,A8) -> 12956.301 | K8: =SUMIFS(Daily!$H$6:$H$2400,Daily!$B$6:$B$2400,A8) -> 0 | L8: =J8+K8 -> 12956.301 | M8: =P7 -> 8776.8491 | N8: =SUMIFS(Cash_Events!$H$6:$H$20,Cash_Events!$C$6:$C$20,"rAGMF",Cash_Events!$D$6:$D$20,"JV",Cash_Events!$M$6:$M$20,A8) -> 0 | O8: =SUMIFS(Cash_Events!$H$6:$H$20,Cash_Events!$C$6:$C$20,"rAGMF",Cash_Events!$D$6:$D$20,"800S",Cash_Events!$M$6:$M$20,A8) -> 0 | P8: =M8+J8-N8-O8 -> 21733.15 | Q8: =S7 -> 0 | R8: =SUMIFS(Cash_Events!$I$6:$I$20,Cash_Events!$C$6:$C$20,"rAGMF",Cash_Events!$M$6:$M$20,A8) -> 0 | S8: =Q8+K8-R8 -> 0 | T8: =P8+S8 -> 21733.15 | U8: =G8+T8 -> 1521733.2 | V8: =V7+L8 -> 21733.15 | W8: =W7+N8+O8+R8 -> 0 | X8: =ROUND(V8-W8-T8,2) -> 0
A9: =EOMONTH(A8,1) -> 44895 | B9: =A8 -> 44865 | C9: =A9-B9 -> 30 | D9: =IF(A9<=EOMONTH(Inputs!$B$18,-1),"Actual","Projection") -> Actual | E9: =G8 -> 1500000 | F9: =SUMIFS(Cash_Events!$G$6:$G$20,Cash_Events!$C$6:$C$20,"rAGMF",Cash_Events!$M$6:$M$20,A9) -> 0 | G9: =E9-F9 -> 1500000 | H9: =VLOOKUP(A9-1,Inputs!$A$40:$B$48,2,TRUE()) -> 0.034199997 | I9: =H9+Inputs!B10 -> 0.1017 | J9: =SUMIFS(Daily!$G$6:$G$2400,Daily!$B$6:$B$2400,A9) -> 12538.356 | K9: =SUMIFS(Daily!$H$6:$H$2400,Daily!$B$6:$B$2400,A9) -> 0 | L9: =J9+K9 -> 12538.356 | M9: =P8 -> 21733.15 | N9: =SUMIFS(Cash_Events!$H$6:$H$20,Cash_Events!$C$6:$C$20,"rAGMF",Cash_Events!$D$6:$D$20,"JV",Cash_Events!$M$6:$M$20,A9) -> 0 | O9: =SUMIFS(Cash_Events!$H$6:$H$20,Cash_Events!$C$6:$C$20,"rAGMF",Cash_Events!$D$6:$D$20,"800S",Cash_Events!$M$6:$M$20,A9) -> 0 | P9: =M9+J9-N9-O9 -> 34271.506 | Q9: =S8 -> 0 | R9: =SUMIFS(Cash_Events!$I$6:$I$20,Cash_Events!$C$6:$C$20,"rAGMF",Cash_Events!$M$6:$M$20,A9) -> 0 | S9: =Q9+K9-R9 -> 0 | T9: =P9+S9 -> 34271.506 | U9: =G9+T9 -> 1534271.5 | V9: =V8+L9 -> 34271.506 | W9: =W8+N9+O9+R9 -> 0 | X9: =ROUND(V9-W9-T9,2) -> 0
A10: =EOMONTH(A9,1) -> 44926 | B10: =A9 -> 44895 | C10: =A10-B10 -> 31 | D10: =IF(A10<=EOMONTH(Inputs!$B$18,-1),"Actual","Projection") -> Actual | E10: =G9 -> 1500000 | F10: =SUMIFS(Cash_Events!$G$6:$G$20,Cash_Events!$C$6:$C$20,"rAGMF",Cash_Events!$M$6:$M$20,A10) -> 0 | G10: =E10-F10 -> 1500000 | H10: =VLOOKUP(A10-1,Inputs!$A$40:$B$48,2,TRUE()) -> 0.034199997 | I10: =H10+Inputs!B10 -> 0.1017 | J10: =SUMIFS(Daily!$G$6:$G$2400,Daily!$B$6:$B$2400,A10) -> 12956.301 | K10: =SUMIFS(Daily!$H$6:$H$2400,Daily!$B$6:$B$2400,A10) -> 0 | L10: =J10+K10 -> 12956.301 | M10: =P9 -> 34271.506 | N10: =SUMIFS(Cash_Events!$H$6:$H$20,Cash_Events!$C$6:$C$20,"rAGMF",Cash_Events!$D$6:$D$20,"JV",Cash_Events!$M$6:$M$20,A10) -> 0 | O10: =SUMIFS(Cash_Events!$H$6:$H$20,Cash_Events!$C$6:$C$20,"rAGMF",Cash_Events!$D$6:$D$20,"800S",Cash_Events!$M$6:$M$20,A10) -> 0 | P10: =M10+J10-N10-O10 -> 47227.807 | Q10: =S9 -> 0 | R10: =SUMIFS(Cash_Events!$I$6:$I$20,Cash_Events!$C$6:$C$20,"rAGMF",Cash_Events!$M$6:$M$20,A10) -> 0 | S10: =Q10+K10-R10 -> 0 | T10: =P10+S10 -> 47227.807 | U10: =G10+T10 -> 1547227.8 | V10: =V9+L10 -> 47227.807 | W10: =W9+N10+O10+R10 -> 0 | X10: =ROUND(V10-W10-T10,2) -> 0
A11: =EOMONTH(A10,1) -> 44957 | B11: =A10 -> 44926 | C11: =A11-B11 -> 31 | D11: =IF(A11<=EOMONTH(Inputs!$B$18,-1),"Actual","Projection") -> Actual | E11: =G10 -> 1500000 | F11: =SUMIFS(Cash_Events!$G$6:$G$20,Cash_Events!$C$6:$C$20,"rAGMF",Cash_Events!$M$6:$M$20,A11) -> 0 | G11: =E11-F11 -> 1500000 | H11: =VLOOKUP(A11-1,Inputs!$A$40:$B$48,2,TRUE()) -> 0.034199997 | I11: =H11+Inputs!B10 -> 0.1017 | J11: =SUMIFS(Daily!$G$6:$G$2400,Daily!$B$6:$B$2400,A11) -> 12956.301 | K11: =SUMIFS(Daily!$H$6:$H$2400,Daily!$B$6:$B$2400,A11) -> 0 | L11: =J11+K11 -> 12956.301 | M11: =P10 -> 47227.807 | N11: =SUMIFS(Cash_Events!$H$6:$H$20,Cash_Events!$C$6:$C$20,"rAGMF",Cash_Events!$D$6:$D$20,"JV",Cash_Events!$M$6:$M$20,A11) -> 0 | O11: =SUMIFS(Cash_Events!$H$6:$H$20,Cash_Events!$C$6:$C$20,"rAGMF",Cash_Events!$D$6:$D$20,"800S",Cash_Events!$M$6:$M$20,A11) -> 0 | P11: =M11+J11-N11-O11 -> 60184.108 | Q11: =S10 -> 0 | R11: =SUMIFS(Cash_Events!$I$6:$I$20,Cash_Events!$C$6:$C$20,"rAGMF",Cash_Events!$M$6:$M$20,A11) -> 0 | S11: =Q11+K11-R11 -> 0 | T11: =P11+S11 -> 60184.108 | U11: =G11+T11 -> 1560184.1 | V11: =V10+L11 -> 60184.108 | W11: =W10+N11+O11+R11 -> 0 | X11: =ROUND(V11-W11-T11,2) -> 0
A12: =EOMONTH(A11,1) -> 44985 | B12: =A11 -> 44957 | C12: =A12-B12 -> 28 | D12: =IF(A12<=EOMONTH(Inputs!$B$18,-1),"Actual","Projection") -> Actual | E12: =G11 -> 1500000 | F12: =SUMIFS(Cash_Events!$G$6:$G$20,Cash_Events!$C$6:$C$20,"rAGMF",Cash_Events!$M$6:$M$20,A12) -> 0 | G12: =E12-F12 -> 1500000 | H12: =VLOOKUP(A12-1,Inputs!$A$40:$B$48,2,TRUE()) -> 0.034199997 | I12: =H12+Inputs!B10 -> 0.1017 | J12: =SUMIFS(Daily!$G$6:$G$2400,Daily!$B$6:$B$2400,A12) -> 11702.465 | K12: =SUMIFS(Daily!$H$6:$H$2400,Daily!$B$6:$B$2400,A12) -> 0 | L12: =J12+K12 -> 11702.465 | M12: =P11 -> 60184.108 | N12: =SUMIFS(Cash_Events!$H$6:$H$20,Cash_Events!$C$6:$C$20,"rAGMF",Cash_Events!$D$6:$D$20,"JV",Cash_Events!$M$6:$M$20,A12) -> 0 | O12: =SUMIFS(Cash_Events!$H$6:$H$20,Cash_Events!$C$6:$C$20,"rAGMF",Cash_Events!$D$6:$D$20,"800S",Cash_Events!$M$6:$M$20,A12) -> 0 | P12: =M12+J12-N12-O12 -> 71886.573 | Q12: =S11 -> 0 | R12: =SUMIFS(Cash_Events!$I$6:$I$20,Cash_Events!$C$6:$C$20,"rAGMF",Cash_Events!$M$6:$M$20,A12) -> 0 | S12: =Q12+K12-R12 -> 0 | T12: =P12+S12 -> 71886.573 | U12: =G12+T12 -> 1571886.6 | V12: =V11+L12 -> 71886.573 | W12: =W11+N12+O12+R12 -> 0 | X12: =ROUND(V12-W12-T12,2) -> 0
A13: =EOMONTH(A12,1) -> 45016 | B13: =A12 -> 44985 | C13: =A13-B13 -> 31 | D13: =IF(A13<=EOMONTH(Inputs!$B$18,-1),"Actual","Projection") -> Actual | E13: =G12 -> 1500000 | F13: =SUMIFS(Cash_Events!$G$6:$G$20,Cash_Events!$C$6:$C$20,"rAGMF",Cash_Events!$M$6:$M$20,A13) -> 0 | G13: =E13-F13 -> 1500000 | H13: =VLOOKUP(A13-1,Inputs!$A$40:$B$48,2,TRUE()) -> 0.0521501 | I13: =H13+Inputs!B10 -> 0.1196501 | J13: =SUMIFS(Daily!$G$6:$G$2400,Daily!$B$6:$B$2400,A13) -> 14579.187 | K13: =SUMIFS(Daily!$H$6:$H$2400,Daily!$B$6:$B$2400,A13) -> 0 | L13: =J13+K13 -> 14579.187 | M13: =P12 -> 71886.573 | N13: =SUMIFS(Cash_Events!$H$6:$H$20,Cash_Events!$C$6:$C$20,"rAGMF",Cash_Events!$D$6:$D$20,"JV",Cash_Events!$M$6:$M$20,A13) -> 75648.08 | O13: =SUMIFS(Cash_Events!$H$6:$H$20,Cash_Events!$C$6:$C$20,"rAGMF",Cash_Events!$D$6:$D$20,"800S",Cash_Events!$M$6:$M$20,A13) -> 0 | P13: =M13+J13-N13-O13 -> 10817.68 | Q13: =S12 -> 0 | R13: =SUMIFS(Cash_Events!$I$6:$I$20,Cash_Events!$C$6:$C$20,"rAGMF",Cash_Events!$M$6:$M$20,A13) -> 0 | S13: =Q13+K13-R13 -> 0 | T13: =P13+S13 -> 10817.68 | U13: =G13+T13 -> 1510817.7 | V13: =V12+L13 -> 86465.76 | W13: =W12+N13+O13+R13 -> 75648.08 | X13: =ROUND(V13-W13-T13,2) -> 0 | Y13: Coupon 1 paid by JV 07/03/2023; reset 09/03
A14: =EOMONTH(A13,1) -> 45046 | B14: =A13 -> 45016 | C14: =A14-B14 -> 30 | D14: =IF(A14<=EOMONTH(Inputs!$B$18,-1),"Actual","Projection") -> Actual | E14: =G13 -> 1500000 | F14: =SUMIFS(Cash_Events!$G$6:$G$20,Cash_Events!$C$6:$C$20,"rAGMF",Cash_Events!$M$6:$M$20,A14) -> 0 | G14: =E14-F14 -> 1500000 | H14: =VLOOKUP(A14-1,Inputs!$A$40:$B$48,2,TRUE()) -> 0.0521501 | I14: =H14+Inputs!B10 -> 0.1196501 | J14: =SUMIFS(Daily!$G$6:$G$2400,Daily!$B$6:$B$2400,A14) -> 14751.382 | K14: =SUMIFS(Daily!$H$6:$H$2400,Daily!$B$6:$B$2400,A14) -> 0 | L14: =J14+K14 -> 14751.382 | M14: =P13 -> 10817.68 | N14: =SUMIFS(Cash_Events!$H$6:$H$20,Cash_Events!$C$6:$C$20,"rAGMF",Cash_Events!$D$6:$D$20,"JV",Cash_Events!$M$6:$M$20,A14) -> 0 | O14: =SUMIFS(Cash_Events!$H$6:$H$20,Cash_Events!$C$6:$C$20,"rAGMF",Cash_Events!$D$6:$D$20,"800S",Cash_Events!$M$6:$M$20,A14) -> 0 | P14: =M14+J14-N14-O14 -> 25569.062 | Q14: =S13 -> 0 | R14: =SUMIFS(Cash_Events!$I$6:$I$20,Cash_Events!$C$6:$C$20,"rAGMF",Cash_Events!$M$6:$M$20,A14) -> 0 | S14: =Q14+K14-R14 -> 0 | T14: =P14+S14 -> 25569.062 | U14: =G14+T14 -> 1525569.1 | V14: =V13+L14 -> 101217.14 | W14: =W13+N14+O14+R14 -> 75648.08 | X14: =ROUND(V14-W14-T14,2) -> 0
A15: =EOMONTH(A14,1) -> 45077 | B15: =A14 -> 45046 | C15: =A15-B15 -> 31 | D15: =IF(A15<=EOMONTH(Inputs!$B$18,-1),"Actual","Projection") -> Actual | E15: =G14 -> 1500000 | F15: =SUMIFS(Cash_Events!$G$6:$G$20,Cash_Events!$C$6:$C$20,"rAGMF",Cash_Events!$M$6:$M$20,A15) -> 0 | G15: =E15-F15 -> 1500000 | H15: =VLOOKUP(A15-1,Inputs!$A$40:$B$48,2,TRUE()) -> 0.0521501 | I15: =H15+Inputs!B10 -> 0.1196501 | J15: =SUMIFS(Daily!$G$6:$G$2400,Daily!$B$6:$B$2400,A15) -> 15243.095 | K15: =SUMIFS(Daily!$H$6:$H$2400,Daily!$B$6:$B$2400,A15) -> 0 | L15: =J15+K15 -> 15243.095 | M15: =P14 -> 25569.062 | N15: =SUMIFS(Cash_Events!$H$6:$H$20,Cash_Events!$C$6:$C$20,"rAGMF",Cash_Events!$D$6:$D$20,"JV",Cash_Events!$M$6:$M$20,A15) -> 0 | O15: =SUMIFS(Cash_Events!$H$6:$H$20,Cash_Events!$C$6:$C$20,"rAGMF",Cash_Events!$D$6:$D$20,"800S",Cash_Events!$M$6:$M$20,A15) -> 0 | P15: =M15+J15-N15-O15 -> 40812.157 | Q15: =S14 -> 0 | R15: =SUMIFS(Cash_Events!$I$6:$I$20,Cash_Events!$C$6:$C$20,"rAGMF",Cash_Events!$M$6:$M$20,A15) -> 0 | S15: =Q15+K15-R15 -> 0 | T15: =P15+S15 -> 40812.157 | U15: =G15+T15 -> 1540812.2 | V15: =V14+L15 -> 116460.24 | W15: =W14+N15+O15+R15 -> 75648.08 | X15: =ROUND(V15-W15-T15,2) -> 0
A16: =EOMONTH(A15,1) -> 45107 | B16: =A15 -> 45077 | C16: =A16-B16 -> 30 | D16: =IF(A16<=EOMONTH(Inputs!$B$18,-1),"Actual","Projection") -> Actual | E16: =G15 -> 1500000 | F16: =SUMIFS(Cash_Events!$G$6:$G$20,Cash_Events!$C$6:$C$20,"rAGMF",Cash_Events!$M$6:$M$20,A16) -> 0 | G16: =E16-F16 -> 1500000 | H16: =VLOOKUP(A16-1,Inputs!$A$40:$B$48,2,TRUE()) -> 0.0521501 | I16: =H16+Inputs!B10 -> 0.1196501 | J16: =SUMIFS(Daily!$G$6:$G$2400,Daily!$B$6:$B$2400,A16) -> 14751.382 | K16: =SUMIFS(Daily!$H$6:$H$2400,Daily!$B$6:$B$2400,A16) -> 0 | L16: =J16+K16 -> 14751.382 | M16: =P15 -> 40812.157 | N16: =SUMIFS(Cash_Events!$H$6:$H$20,Cash_Events!$C$6:$C$20,"rAGMF",Cash_Events!$D$6:$D$20,"JV",Cash_Events!$M$6:$M$20,A16) -> 0 | O16: =SUMIFS(Cash_Events!$H$6:$H$20,Cash_Events!$C$6:$C$20,"rAGMF",Cash_Events!$D$6:$D$20,"800S",Cash_Events!$M$6:$M$20,A16) -> 0 | P16: =M16+J16-N16-O16 -> 55563.54 | Q16: =S15 -> 0 | R16: =SUMIFS(Cash_Events!$I$6:$I$20,Cash_Events!$C$6:$C$20,"rAGMF",Cash_Events!$M$6:$M$20,A16) -> 0 | S16: =Q16+K16-R16 -> 0 | T16: =P16+S16 -> 55563.54 | U16: =G16+T16 -> 1555563.5 | V16: =V15+L16 -> 131211.62 | W16: =W15+N16+O16+R16 -> 75648.08 | X16: =ROUND(V16-W16-T16,2) -> 0
A17: =EOMONTH(A16,1) -> 45138 | B17: =A16 -> 45107 | C17: =A17-B17 -> 31 | D17: =IF(A17<=EOMONTH(Inputs!$B$18,-1),"Actual","Projection") -> Actual | E17: =G16 -> 1500000 | F17: =SUMIFS(Cash_Events!$G$6:$G$20,Cash_Events!$C$6:$C$20,"rAGMF",Cash_Events!$M$6:$M$20,A17) -> 0 | G17: =E17-F17 -> 1500000 | H17: =VLOOKUP(A17-1,Inputs!$A$40:$B$48,2,TRUE()) -> 0.0521501 | I17: =H17+Inputs!B10 -> 0.1196501 | J17: =SUMIFS(Daily!$G$6:$G$2400,Daily!$B$6:$B$2400,A17) -> 15243.095 | K17: =SUMIFS(Daily!$H$6:$H$2400,Daily!$B$6:$B$2400,A17) -> 0 | L17: =J17+K17 -> 15243.095 | M17: =P16 -> 55563.54 | N17: =SUMIFS(Cash_Events!$H$6:$H$20,Cash_Events!$C$6:$C$20,"rAGMF",Cash_Events!$D$6:$D$20,"JV",Cash_Events!$M$6:$M$20,A17) -> 0 | O17: =SUMIFS(Cash_Events!$H$6:$H$20,Cash_Events!$C$6:$C$20,"rAGMF",Cash_Events!$D$6:$D$20,"800S",Cash_Events!$M$6:$M$20,A17) -> 0 | P17: =M17+J17-N17-O17 -> 70806.635 | Q17: =S16 -> 0 | R17: =SUMIFS(Cash_Events!$I$6:$I$20,Cash_Events!$C$6:$C$20,"rAGMF",Cash_Events!$M$6:$M$20,A17) -> 0 | S17: =Q17+K17-R17 -> 0 | T17: =P17+S17 -> 70806.635 | U17: =G17+T17 -> 1570806.6 | V17: =V16+L17 -> 146454.71 | W17: =W16+N17+O17+R17 -> 75648.08 | X17: =ROUND(V17-W17-T17,2) -> 0
A18: =EOMONTH(A17,1) -> 45169 | B18: =A17 -> 45138 | C18: =A18-B18 -> 31 | D18: =IF(A18<=EOMONTH(Inputs!$B$18,-1),"Actual","Projection") -> Actual | E18: =G17 -> 1500000 | F18: =SUMIFS(Cash_Events!$G$6:$G$20,Cash_Events!$C$6:$C$20,"rAGMF",Cash_Events!$M$6:$M$20,A18) -> 0 | G18: =E18-F18 -> 1500000 | H18: =VLOOKUP(A18-1,Inputs!$A$40:$B$48,2,TRUE()) -> 0.0521501 | I18: =H18+Inputs!B10 -> 0.1196501 | J18: =SUMIFS(Daily!$G$6:$G$2400,Daily!$B$6:$B$2400,A18) -> 15243.095 | K18: =SUMIFS(Daily!$H$6:$H$2400,Daily!$B$6:$B$2400,A18) -> 0 | L18: =J18+K18 -> 15243.095 | M18: =P17 -> 70806.635 | N18: =SUMIFS(Cash_Events!$H$6:$H$20,Cash_Events!$C$6:$C$20,"rAGMF",Cash_Events!$D$6:$D$20,"JV",Cash_Events!$M$6:$M$20,A18) -> 0 | O18: =SUMIFS(Cash_Events!$H$6:$H$20,Cash_Events!$C$6:$C$20,"rAGMF",Cash_Events!$D$6:$D$20,"800S",Cash_Events!$M$6:$M$20,A18) -> 0 | P18: =M18+J18-N18-O18 -> 86049.729 | Q18: =S17 -> 0 | R18: =SUMIFS(Cash_Events!$I$6:$I$20,Cash_Events!$C$6:$C$20,"rAGMF",Cash_Events!$M$6:$M$20,A18) -> 0 | S18: =Q18+K18-R18 -> 0 | T18: =P18+S18 -> 86049.729 | U18: =G18+T18 -> 1586049.7 | V18: =V17+L18 -> 161697.81 | W18: =W17+N18+O18+R18 -> 75648.08 | X18: =ROUND(V18-W18-T18,2) -> 0
A19: =EOMONTH(A18,1) -> 45199 | B19: =A18 -> 45169 | C19: =A19-B19 -> 30 | D19: =IF(A19<=EOMONTH(Inputs!$B$18,-1),"Actual","Projection") -> Actual | E19: =G18 -> 1500000 | F19: =SUMIFS(Cash_Events!$G$6:$G$20,Cash_Events!$C$6:$C$20,"rAGMF",Cash_Events!$M$6:$M$20,A19) -> 0 | G19: =E19-F19 -> 1500000 | H19: =VLOOKUP(A19-1,Inputs!$A$40:$B$48,2,TRUE()) -> 0.0547601 | I19: =H19+Inputs!B10 -> 0.1222601 | J19: =SUMIFS(Daily!$G$6:$G$2400,Daily!$B$6:$B$2400,A19) -> 14955.177 | K19: =SUMIFS(Daily!$H$6:$H$2400,Daily!$B$6:$B$2400,A19) -> 1561.6438 | L19: =J19+K19 -> 16516.821 | M19: =P18 -> 86049.729 | N19: =SUMIFS(Cash_Events!$H$6:$H$20,Cash_Events!$C$6:$C$20,"rAGMF",Cash_Events!$D$6:$D$20,"JV",Cash_Events!$M$6:$M$20,A19) -> 0 | O19: =SUMIFS(Cash_Events!$H$6:$H$20,Cash_Events!$C$6:$C$20,"rAGMF",Cash_Events!$D$6:$D$20,"800S",Cash_Events!$M$6:$M$20,A19) -> 0 | P19: =M19+J19-N19-O19 -> 101004.91 | Q19: =S18 -> 0 | R19: =SUMIFS(Cash_Events!$I$6:$I$20,Cash_Events!$C$6:$C$20,"rAGMF",Cash_Events!$M$6:$M$20,A19) -> 0 | S19: =Q19+K19-R19 -> 1561.6438 | T19: =P19+S19 -> 102566.55 | U19: =G19+T19 -> 1602566.6 | V19: =V18+L19 -> 178214.63 | W19: =W18+N19+O19+R19 -> 75648.08 | X19: =ROUND(V19-W19-T19,2) -> 0 | Y19: Coupon 2 missed 11/09/2023 - default interest starts
A20: =EOMONTH(A19,1) -> 45230 | B20: =A19 -> 45199 | C20: =A20-B20 -> 31 | D20: =IF(A20<=EOMONTH(Inputs!$B$18,-1),"Actual","Projection") -> Actual | E20: =G19 -> 1500000 | F20: =SUMIFS(Cash_Events!$G$6:$G$20,Cash_Events!$C$6:$C$20,"rAGMF",Cash_Events!$M$6:$M$20,A20) -> 0 | G20: =E20-F20 -> 1500000 | H20: =VLOOKUP(A20-1,Inputs!$A$40:$B$48,2,TRUE()) -> 0.0547601 | I20: =H20+Inputs!B10 -> 0.1222601 | J20: =SUMIFS(Daily!$G$6:$G$2400,Daily!$B$6:$B$2400,A20) -> 15575.602 | K20: =SUMIFS(Daily!$H$6:$H$2400,Daily!$B$6:$B$2400,A20) -> 2547.9452 | L20: =J20+K20 -> 18123.547 | M20: =P19 -> 101004.91 | N20: =SUMIFS(Cash_Events!$H$6:$H$20,Cash_Events!$C$6:$C$20,"rAGMF",Cash_Events!$D$6:$D$20,"JV",Cash_Events!$M$6:$M$20,A20) -> 0 | O20: =SUMIFS(Cash_Events!$H$6:$H$20,Cash_Events!$C$6:$C$20,"rAGMF",Cash_Events!$D$6:$D$20,"800S",Cash_Events!$M$6:$M$20,A20) -> 0 | P20: =M20+J20-N20-O20 -> 116580.51 | Q20: =S19 -> 1561.6438 | R20: =SUMIFS(Cash_Events!$I$6:$I$20,Cash_Events!$C$6:$C$20,"rAGMF",Cash_Events!$M$6:$M$20,A20) -> 0 | S20: =Q20+K20-R20 -> 4109.589 | T20: =P20+S20 -> 120690.1 | U20: =G20+T20 -> 1620690.1 | V20: =V19+L20 -> 196338.18 | W20: =W19+N20+O20+R20 -> 75648.08 | X20: =ROUND(V20-W20-T20,2) -> 0
