Workbook

Sheet Read Me
A1: 800 Super GAEA - Loan & Interest Clean-up (responsAbility + Healthier loans)
A2: Prepared from: client file (GAEA Dual Loan Lifecycle v6), our 2024 Loan Reconciliation, and the QuickBooks General Ledger Jan 2022 - Dec 2024. All amounts in USD.
A5: WHAT IS IN THIS FILE (read the tabs from left to right)
A6: 1 | B6: Client vs Our Recon - every item compared side by side, with colours (legend below).
A7: 2 | B7: QuickBooks - Delete & Edit - the exact entries in QuickBooks to DELETE, and the ones to EDIT (change the account only).
A8: 3 | B8: Correcting Entries - the new journal entries to post after the deletions, so the books show the correct flow.
A9: 4 | B9: Before vs After - what the balances look like now in QuickBooks vs after the clean-up (with a check that it balances).
A10: 5 | B10: Option B - Locked Years - use this instead of tabs 2-3 for 2022/2023 if those years are already closed/audited and cannot be changed.
A12: COLOUR LEGEND (tab 1)
B13: BLUE = item is in our recon AND agrees with the client file.
B14: GREEN = item is in the client file but was NOT captured in our recon.
B15: ORANGE = item is in both files, but the amounts are different (difference shown + reason).
B16: GREY = item is only in our recon (not in the client file).
A18: THE STORY IN PLAIN WORDS
A19: • | B19: In Sept 2022 the company borrowed USD 1.5M from responsAbility (rA) and USD 1.5M from Healthier (FHL). Interest = 6-month SOFR + 6.75% a year.
A20: • | B20: The company paid only the first interest payment (March 2023). From Sept 2023 it stopped paying, so the lenders also charged 2% "late" (default) interest.
A21: • | B21: In June 2024 the shareholder 800 Super WM Pte (800S) paid 51% for the company: USD 1,530,000 principal + USD 215,676.83 interest. The company now owes this USD 1,745,676.83 to 800S instead.
A22: • | B22: The client file is built from the lenders' own calculation and ties to the lenders to the cent. Our recon used some ESTIMATED rates (e.g. 13.91% for rA from March 2024), so our 2024-2025 interest is too high.
A23: • | B23: So: we use the CLIENT FILE figures for the lender interest in the correcting entries. We keep our recon's 800S interest (6% per the 800S loan agreement), which the client file does not cover - please confirm it with the client.
A25: WHAT IS WRONG IN QUICKBOOKS TODAY
A26: 1 | B26: The two loans (USD 3M) were recorded in 20520 Related Party PNP-Holding, as if the money came from a group company. They should be in their own loan accounts.
A27: 2 | B27: No interest was recorded for 2022 (Sep-Dec). The March 2023 payment was put fully into 2023 expense.
A28: 3 | B28: 2023 interest was recorded with rough monthly guesses (USD 316,881.39) into 20010 Operating Account Payable (trade payables) instead of interest payable accounts.
A29: 4 | B29: 2024 interest was already re-posted (INT24-001 to INT24-012) using our recon's estimated rates - lender interest is overstated by USD 18,777.99 for 2024.
A30: 5 | B30: The June 2024 800S payments (LOAN24-001/002) are dated 30 June instead of the real dates (13 June interest, 28 June principal) and hit the wrong accounts (20010 and 20520).
A31: 6 | B31: NEW FINDING (not in either file): QuickBooks booked and PAID 14% withholding tax (WHT) on this interest every month from May 2023 to July 2024 - USD 74,668.47 in total - by reducing 20010 (as if the lenders were paid less). The lenders were not paid less (the loan has a tax gross-up clause), so this tax is the company's own cost and must move to 63025 WTH 14% Non Deductible. Our recon had said these WHT entries were unrelated - they are related (each one is exactly 14% of that month's interest accrual).
A33: THE RESULT AFTER CLEAN-UP (31 Dec 2024)
A34: • | B34: Loan payable - responsAbility USD 735,000 | Loan payable - Healthier USD 735,000 | Shareholder loan 800S USD 1,745,676.83
A35: • | B35: Interest payable - responsAbility USD 201,893.06 | Interest payable - Healthier USD 201,381.69 (= client file / lender figures) | Interest payable - 800S USD 54,115.97
A36: • | B36: Interest expense: 2022 USD 94,455.62 | 2023 USD 368,774.94 | 2024 USD 363,640.82 (incl. 800S USD 54,115.97)
A38: OPEN POINTS / DECISIONS NEEDED
A39: 1 | B39: If 2022 and 2023 were already reported to the auditors (our recon says they were), do NOT edit those years - use tab "Option B - Locked Years" instead.
A40: 2 | B40: 800S interest at 6%: in our recon and already in QuickBooks, but not in the client file. Confirm with the client that 800S charges this interest.
A41: 3 | B41: Extra 14% WHT (gross-up): by law the WHT should be 14% of the grossed-up interest. The company paid 14% of rough accruals only. Optional top-up entries are in tab 3, Part C - confirm with the tax adviser before posting.
A42: 4 | B42: Penalty (default) interest: the client's books note "RA agreed to waive penalties", but the lenders' June 2026 figure still includes it. Get the waiver in writing, otherwise keep it booked (as we do here).
A43: 5 | B43: 2025 and 2026: this GL ends Dec 2024. After this clean-up, 2025-2026 interest must also be booked per the client file (client says JV books need USD 210,826.52 catch-up to 30 Sep 2026 on its own figures).
A44: 6 | B44: USD 15,000 fee kept by rA at drawdown: booked as bank charges (66020). The client file calls it a financing fee. Fine to leave as is (no change proposed).

Sheet Client vs Our Recon
A1: Client file vs Our 2024 Loan Reconciliation
A2: Blue = in our recon & same as client | Green = in client file, not in our recon | Orange = in both but different | Grey = only in our recon. Difference = Client - Our recon.
A4: # | B4: Item | C4: Client file | D4: Our recon | E4: Difference | F4: Result | G4: What it means
B5: A. Loan basics
A6: 1 | B6: Principal - responsAbility (rA) | C6: 1500000 | D6: 1500000 | E6: =C6-D6 -> 0 | F6: Same | G6: Same loan amount.
A7: 2 | B7: Principal - Healthier (FHL) | C7: 1500000 | D7: 1500000 | E7: =C7-D7 -> 0 | F7: Same | G7: Same loan amount.
A8: 3 | B8: Interest start date (both loans) | C8: 09-Sep-2022 | D8: 09-Sep-2022 | F8: Same | G8: Same. Cash arrived in ABA bank on 12-Sep-2022.
A9: 4 | B9: Cash received - rA | C9: 1485000 | D9: 1485000 | E9: =C9-D9 -> 0 | F9: Same | G9: Same. rA kept USD 15,000 (1% upfront fee).
A10: 5 | B10: Cash received - FHL | C10: 1499970 | D10: 1499970 | E10: =C10-D10 -> 0 | F10: Same | G10: Same. USD 30 bank fee taken off.
A11: 6 | B11: Upfront fee kept by rA | C11: 15000 | D11: 15000 | E11: =C11-D11 -> 0 | F11: Same | G11: Same amount. Client calls it a financing fee; we booked it as bank charges.
A12: 7 | B12: Interest rate formula | C12: 6M SOFR + 6.75% | D12: 6M SOFR + 6.75% | F12: Same | G12: Same.
A13: 8 | B13: Late (default) interest | C13: 2% a year on principal | D13: 2% a year on principal | F13: Same | G13: Same.
A14: 9 | B14: Default interest start date | C14: rA 11-Sep-2023 / FHL 15-Sep-2023 | D14: rA 11-Sep-2023 / FHL 15-Sep-2023 | F14: Same | G14: Same (first missed payment).
B15: B. Payments
A16: 10 | B16: 1st interest payment - rA (Mar 2023) | C16: 75648.08 | D16: 75648.08 | E16: =C16-D16 -> 0 | F16: Same | G16: Same.
A17: 11 | B17: 1st interest payment - FHL (Mar 2023) | C17: 78155.75 | D17: 78155.75 | E17: =C17-D17 -> 0 | F17: Same | G17: Same amount. Client dates it 07-Mar-2023, QuickBooks 10-Mar-2023 (minor).
A18: 12 | B18: Missed Sep 2023 payment - rA | C18: 91458.57 | D18: 91458.57 | E18: =C18-D18 -> 0 | F18: Same | G18: Same.
A19: 13 | B19: Missed Sep 2023 payment - FHL | C19: 90529.74 | D19: 90529.74 | E19: =C19-D19 -> 0 | F19: Same | G19: Same.
A20: 14 | B20: Interest paid by 800S for rA (13-Jun-2024) | C20: 109165.69 | D20: 109165.69 | E20: =C20-D20 -> 0 | F20: Same | G20: Same (incl. USD 1,163.29 moved from the principal remittance).
A21: 15 | B21: Interest paid by 800S for FHL (13-Jun-2024) | C21: 106511.14 | D21: 106511.14 | E21: =C21-D21 -> 0 | F21: Same | G21: Same (bank slip 107,674.43 less USD 1,163.29 moved to principal).
A22: 16 | B22: Principal paid by 800S, each loan (28-Jun-2024) | C22: 765000 | D22: 765000 | E22: =C22-D22 -> 0 | F22: Same | G22: Same - 51% of each loan.
A23: 17 | B23: Principal still owed, each loan | C23: 735000 | D23: 735000 | E23: =C23-D23 -> 0 | F23: Same | G23: Same - 49% left.
A24: 18 | B24: New shareholder loan owed to 800S | C24: 1745676.8 | D24: 1745676.8 | E24: =C24-D24 -> 0 | F24: Same | G24: Same (1,530,000 principal + 215,676.83 interest).
B25: C. Lender figures at 5-Apr-2024 (default notices)
A26: 19 | B26: FHL unpaid interest | C26: 192181.77 | D26: 192181.77 | E26: =C26-D26 -> 0 | F26: Same | G26: Same - ties to the default notice.
A27: 20 | B27: FHL default interest | C27: 16663.6 | D27: 16663.6 | E27: =C27-D27 -> 0 | F27: Same | G27: Same.
A28: 21 | B28: rA default interest | C28: 16992.36 | D28: 16992.36 | E28: =C28-D28 -> 0 | F28: Same | G28: Same.
A29: 22 | B29: rA unpaid interest (client figure worked out from its daily schedule) | C29: 195086.71 | D29: 197058.01 | E29: =C29-D29 -> -1971.3 | F29: Different | G29: Our recon took the default-notice figure, which used 13.91% for 11-Mar to 5-Apr-2024. The lender's later calculation (used by the client) uses 11.99%.
B30: D. Interest expense by year
A31: 23 | B31: 2022 interest - rA | C31: 47227.81 | D31: 47227.81 | E31: =C31-D31 -> 0 | F31: Same | G31: Same.
A32: 24 | B32: 2022 interest - FHL | C32: 47227.81 | D32: 47227.81 | E32: =C32-D32 -> 0 | F32: Same | G32: Same.
A33: 25 | B33: 2023 interest - rA | C33: 184772.83 | D33: 184702.79 | E33: =C33-D33 -> 70.04 | F33: Different | G33: Small: different way of splitting the Sep-23 to Mar-24 interest between 2023 and 2024 (we used days/182 of the notice amount; the lender uses days/365, days/366 for 2024, and its month-end cut-off).
A34: 26 | B34: 2023 interest - FHL | C34: 184002.11 | D34: 183931.16 | E34: =C34-D34 -> 70.95 | F34: Different | G34: Small: same splitting reason as above.
A35: 27 | B35: 2024 interest - rA | C35: 154706.19 | D35: 171965.15 | E35: =C35-D35 -> -17258.96 | F35: Different | G35: BIG: our recon used 13.91% from Mar-2024 (client email). Lender actually charged 11.99% (Mar-Sep 2024) and 11.37% (from Sep 2024).
A36: 28 | B36: 2024 interest - FHL | C36: 154818.66 | D36: 156337.69 | E36: =C36-D36 -> -1519.03 | F36: Different | G36: Our recon kept 12.00% after Sep-2024 (estimate). Lender actual is 11.32%.
A37: 29 | B37: 2025 interest - rA | C37: 95192.37 | D37: 116935.81 | E37: =C37-D37 -> -21743.44 | F37: Different | G37: Same reason - our rates were estimates.
A38: 30 | B38: 2025 interest - FHL | C38: 95034.22 | D38: 102905.45 | E38: =C38-D38 -> -7871.23 | F38: Different | G38: Same reason - our rates were estimates.
A39: 31 | B39: Interest owed to rA at 31-Dec-2024 | C39: 201893.06 | D39: 219081.98 | E39: =C39-D39 -> -17188.92 | F39: Different | G39: Follows from the rate differences above.
A40: 32 | B40: Interest owed to FHL at 31-Dec-2024 | C40: 201381.69 | D40: 202829.77 | E40: =C40-D40 -> -1448.08 | F40: Different | G40: Follows from the rate differences above.
B41: E. In the client file only (not captured in our recon)
...

Sheet QuickBooks - Delete & Edit
A1: Entries in QuickBooks to DELETE or EDIT
A2: These are the entries to delete & edit to match & align with the final Loan & Interest Schedule
A4: # | B4: Action | C4: Date | D4: QB No. | E4: Type | F4: Account now -> should be | G4: Amount | H4: Remarks
A5: 1 | B5: DELETE | C5: 45046 | D5: ADJ2304-008 | E5: Journal Entry | F5: Dr 66045 Interest Expense / Cr 20010 Operating Account Payable | G5: 29158.96 | H5: 2023 interest guessed monthly and put in trade payables. Replaced by the correct monthly interest in "Correcting Entries" tab
A6: 2 | B6: DELETE | C6: 45138 | D6: ADJ2307-002 | E6: Journal Entry | F6: Dr 66045 Interest Expense / Cr 20010 Operating Account Payable | G6: 29158.96 | H6: 2023 interest guessed monthly and put in trade payables. Replaced by the correct monthly interest in "Correcting Entries" tab
A7: 3 | B7: DELETE | C7: 45169 | D7: ADJ2308-003 | E7: Journal Entry | F7: Dr 66045 Interest Expense / Cr 20010 Operating Account Payable | G7: 29158.96 | H7: 2023 interest guessed monthly and put in trade payables. Replaced by the correct monthly interest in "Correcting Entries" tab
A8: 4 | B8: DELETE | C8: 45199 | D8: ADJ2309-003 | E8: Journal Entry | F8: Dr 66045 Interest Expense / Cr 20010 Operating Account Payable | G8: 65819.47 | H8: 2023 interest guessed monthly and put in trade payables. Replaced by the correct monthly interest in "Correcting Entries" tab
A9: 5 | B9: DELETE | C9: 45229 | D9: ADJ2310-003 | E9: Journal Entry | F9: Dr 66045 Interest Expense / Cr 20010 Operating Account Payable | G9: 35089.04 | H9: 2023 interest guessed monthly and put in trade payables. Replaced by the correct monthly interest in "Correcting Entries" tab
A10: 6 | B10: DELETE | C10: 45260 | D10: ADJ2311-003 | E10: Journal Entry | F10: Dr 66045 Interest Expense / Cr 20010 Operating Account Payable | G10: 35089.04 | H10: 2023 interest guessed monthly and put in trade payables. Replaced by the correct monthly interest in "Correcting Entries" tab
A11: 7 | B11: DELETE | C11: 45291 | D11: ADJ2312-004 | E11: Journal Entry | F11: Dr 66045 Interest Expense / Cr 20010 Operating Account Payable | G11: 35089.04 | H11: 2023 interest guessed monthly and put in trade payables. Replaced by the correct monthly interest in "Correcting Entries" tab
A12: 8 | B12: DELETE | C12: 45322 | D12: INT24-001 | E12: Journal Entry | F12: Dr 66045 / Cr 20260, 20261 (and 20262 from Jun) | G12: 36203.78 | H12: 2024 interest posted with our estimated rates (too high for the lenders). Replaced by "Correcting Entries" tab (800S part is re-posted at the same amount).
A13: 9 | B13: DELETE | C13: 45351 | D13: INT24-002 | E13: Journal Entry | F13: Dr 66045 / Cr 20260, 20261 (and 20262 from Jun) | G13: 33868.04 | H13: 2024 interest posted with our estimated rates (too high for the lenders). Replaced by "Correcting Entries" tab (800S part is re-posted at the same amount).
A14: 10 | B14: DELETE | C14: 45382 | D14: INT24-003 | E14: Journal Entry | F14: Dr 66045 / Cr 20260, 20261 (and 20262 from Jun) | G14: 37407.8 | H14: 2024 interest posted with our estimated rates (too high for the lenders). Replaced by "Correcting Entries" tab (800S part is re-posted at the same amount).
A15: 11 | B15: DELETE | C15: 45412 | D15: INT24-004 | E15: Journal Entry | F15: Dr 66045 / Cr 20260, 20261 (and 20262 from Jun) | G15: 36776.27 | H15: 2024 interest posted with our estimated rates (too high for the lenders). Replaced by "Correcting Entries" tab (800S part is re-posted at the same amount).
A16: 12 | B16: DELETE | C16: 45443 | D16: INT24-005 | E16: Journal Entry | F16: Dr 66045 / Cr 20260, 20261 (and 20262 from Jun) | G16: 38000.89 | H16: 2024 interest posted with our estimated rates (too high for the lenders). Replaced by "Correcting Entries" tab (800S part is re-posted at the same amount).
... A45: 41 | B45: DELETE | C45: 45716 | D45: ADJ2502-INT | E45: Bill | F45: Dr 66045 Interest Expense / Cr 20010 Operating Account Payable | G45: 10149.28 | H45: 800S interest for Jan-2025 booked as a bill in trade payables (20010) with the old amount. Not paid. Replaced by LOANINT-2501 in "Correcting Entries" tab (Jan-2025 800S interest = 9,019.33 in 20262).

Sheet Correcting Entries
A1: New Journal Entries to align with Loan & Interest Schedule
A2: These entries are applied after we delete & edit out the necessary entries mentioned in the "QuickBooks - Delete & Edit" Tab
A4: To Establish the new loan from 800 SWM
A5: Journal Reference | B5: Date | C5: Account | D5: Debit | E5: Credit | H5: Memo
A6: 800SWM-001 | B6: 45456 | C6: 20261 Interest payable - responsAbility | D6: 109165.69 | H6: 800S paid 51% of the lenders' unpaid interest on our behalf (OCBC 13-Jun-2024). We now owe it to 800S.
A7: 800SWM-001 | B7: 45456 | C7: 20260 Interest payable - Healthier | D7: 106511.14 | H7: 800S paid 51% of the lenders' unpaid interest on our behalf (OCBC 13-Jun-2024). We now owe it to 800S.
A8: 800SWM-001 | B8: 45456 | C8: 20259 Shareholder loan - 800SWM | E8: 215676.83 | H8: 800S paid 51% of the lenders' unpaid interest on our behalf (OCBC 13-Jun-2024). We now owe it to 800S.
A9: 800SWM-002 | B9: 45471 | C9: 20263 Loan payable - responsAbility | D9: 765000 | H9: 800S paid 51% of each loan on our behalf (UOB 28-Jun-2024). We now owe it to 800S.
A10: 800SWM-002 | B10: 45471 | C10: 20264 Loan payable - Healthier | D10: 765000 | H10: 800S paid 51% of each loan on our behalf (UOB 28-Jun-2024). We now owe it to 800S.
A11: 800SWM-002 | B11: 45471 | C11: 20259 Shareholder loan - 800SWM | E11: 1530000 | H11: 800S paid 51% of each loan on our behalf (UOB 28-Jun-2024). We now owe it to 800S.
C12: Total | D12: =SUM(D6:D11) -> 1745676.8 | E12: =SUM(E6:E11) -> 1745676.8 | F12: =IF(ROUND(D12-E12,2)=0,"Balanced","CHECK") -> Balanced
A15: To establish the correct interest accruals | D15: Debit | E15: Credit | F15: Credit | G15: Credit
A16: Entry | B16: Date | C16: Memo | D16: 66045 | E16: 20261 | F16: 20260 | G16: 20262 | H16: Where the amount comes from
A17: LOANINT-2209 | B17: 44834 | C17: Interest for Sep 2022 (lenders) | D17: =SUM(E17:G17) -> 17553.7 | E17: 8776.85 | F17: 8776.85 | H17: From the Loan & Interest Schedule (Tab name: rAGMF_Monthly | FHL_Monthly | 800SWM)
A18: LOANINT-2210 | B18: 44865 | C18: Interest for Oct 2022 (lenders) | D18: =SUM(E18:G18) -> 25912.6 | E18: 12956.3 | F18: 12956.3 | H18: From the Loan & Interest Schedule (Tab name: rAGMF_Monthly | FHL_Monthly | 800SWM)
A19: LOANINT-2211 | B19: 44895 | C19: Interest for Nov 2022 (lenders) | D19: =SUM(E19:G19) -> 25076.72 | E19: 12538.36 | F19: 12538.36 | H19: From the Loan & Interest Schedule (Tab name: rAGMF_Monthly | FHL_Monthly | 800SWM)
A20: LOANINT-2212 | B20: 44926 | C20: Interest for Dec 2022 (lenders) | D20: =SUM(E20:G20) -> 25912.6 | E20: 12956.3 | F20: 12956.3 | H20: From the Loan & Interest Schedule (Tab name: rAGMF_Monthly | FHL_Monthly | 800SWM)
A21: LOANINT-2301 | B21: 44957 | C21: Interest for Jan 2023 (lenders) | D21: =SUM(E21:G21) -> 25912.6 | E21: 12956.3 | F21: 12956.3 | H21: From the Loan & Interest Schedule (Tab name: rAGMF_Monthly | FHL_Monthly | 800SWM)
A22: LOANINT-2302 | B22: 44985 | C22: Interest for Feb 2023 (lenders) | D22: =SUM(E22:G22) -> 23404.92 | E22: 11702.46 | F22: 11702.46 | H22: From the Loan & Interest Schedule (Tab name: rAGMF_Monthly | FHL_Monthly | 800SWM)
A23: LOANINT-2303 | B23: 45016 | C23: Interest for Mar 2023 (lenders) | D23: =SUM(E23:G23) -> 28720.52 | E23: 14579.19 | F23: 14141.33 | H23: From the Loan & Interest Schedule (Tab name: rAGMF_Monthly | FHL_Monthly | 800SWM)
A24: LOANINT-2304 | B24: 45046 | C24: Interest for Apr 2023 (lenders) | D24: =SUM(E24:G24) -> 29511.66 | E24: 14751.38 | F24: 14760.28 | H24: From the Loan & Interest Schedule (Tab name: rAGMF_Monthly | FHL_Monthly | 800SWM)
A25: LOANINT-2305 | B25: 45077 | C25: Interest for May 2023 (lenders) | D25: =SUM(E25:G25) -> 30495.4 | E25: 15243.1 | F25: 15252.3 | H25: From the Loan & Interest Schedule (Tab name: rAGMF_Monthly | FHL_Monthly | 800SWM)
A26: LOANINT-2306 | B26: 45107 | C26: Interest for Jun 2023 (lenders) | D26: =SUM(E26:G26) -> 29511.66 | E26: 14751.38 | F26: 14760.28 | H26: From the Loan & Interest Schedule (Tab name: rAGMF_Monthly | FHL_Monthly | 800SWM)
A27: LOANINT-2307 | B27: 45138 | C27: Interest for Jul 2023 (lenders) | D27: =SUM(E27:G27) -> 30495.38 | E27: 15243.09 | F27: 15252.29 | H27: From the Loan & Interest Schedule (Tab name: rAGMF_Monthly | FHL_Monthly | 800SWM)
A28: LOANINT-2308 | B28: 45169 | C28: Interest for Aug 2023 (lenders) | D28: =SUM(E28:G28) -> 30495.4 | E28: 15243.1 | F28: 15252.3 | H28: From the Loan & Interest Schedule (Tab name: rAGMF_Monthly | FHL_Monthly | 800SWM)
... A37: LOANINT-2405 | B37: 45443 | C37: Interest for May 2024 (lenders, incl. 2% late interest) | D37: =SUM(E37:G37) -> 35556.5 | E37: 17768.66 | F37: 17787.84 | H37: From the Loan & Interest Schedule (Tab name: rAGMF_Monthly | FHL_Monthly | 800SWM)
A38: LOANINT-2406 | B38: 45473 | C38: Interest for Jun 2024 (lenders + 800S) | D38: =SUM(E38:G38) -> 33821.47 | E38: 16610.82 | F38: 16628.76 | G38: 581.89 | H38: From the Loan & Interest Schedule (Tab name: rAGMF_Monthly | FHL_Monthly | 800SWM)
A39: LOANINT-2407 | B39: 45504 | C39: Interest for Jul 2024 (lenders + 800S) | D39: =SUM(E39:G39) -> 26442.01 | E39: 8706.64 | F39: 8716.04 | G39: 9019.33 | H39: From the Loan & Interest Schedule (Tab name: rAGMF_Monthly | FHL_Monthly | 800SWM)
A40: LOANINT-2408 | B40: 45535 | C40: Interest for Aug 2024 (lenders + 800S) | D40: =SUM(E40:G40) -> 26442.01 | E40: 8706.64 | F40: 8716.04 | G40: 9019.33 | H40: From the Loan & Interest Schedule (Tab name: rAGMF_Monthly | FHL_Monthly | 800SWM)
A41: LOANINT-2409 | B41: 45565 | C41: Interest for Sep 2024 (lenders + 800S) | D41: =SUM(E41:G41) -> 25136.22 | E41: 8164.22 | F41: 8243.62 | G41: 8728.38 | H41: From the Loan & Interest Schedule (Tab name: rAGMF_Monthly | FHL_Monthly | 800SWM)
A42: LOANINT-2410 | B42: 45596 | C42: Interest for Oct 2024 (lenders + 800S) | D42: =SUM(E42:G42) -> 25632.38 | E42: 8320.51 | F42: 8292.54 | G42: 9019.33 | H42: From the Loan & Interest Schedule (Tab name: rAGMF_Monthly | FHL_Monthly | 800SWM)
A43: LOANINT-2411 | B43: 45626 | C43: Interest for Nov 2024 (lenders + 800S) | D43: =SUM(E43:G43) -> 24805.54 | E43: 8052.11 | F43: 8025.05 | G43: 8728.38 | H43: From the Loan & Interest Schedule (Tab name: rAGMF_Monthly | FHL_Monthly | 800SWM)
A44: LOANINT-2412 | B44: 45657 | C44: Interest for Dec 2024 (lenders + 800S) | D44: =SUM(E44:G44) -> 25632.39 | E44: 8320.52 | F44: 8292.54 | G44: 9019.33 | H44: From the Loan & Interest Schedule (Tab name: rAGMF_Monthly | FHL_Monthly | 800SWM)
A45: LOANINT-2501 | B45: 45688 | C45: Interest for Jan 2025 (lenders + 800S) | D45: =SUM(E45:G45) -> 25676.43 | E45: 8342.57 | F45: 8314.53 | G45: 9019.33 | H45: From the Loan & Interest Schedule (Tab name: rAGMF_Monthly | FHL_Monthly | 800SWM)
A46: LOANINT-2502 | B46: 45716 | C46: Interest for Feb 2025 (lenders + 800S) | D46: =SUM(E46:G46) -> 23192.95 | E46: 7535.9 | F46: 7510.56 | G46: 8146.49 | H46: From the Loan & Interest Schedule (Tab name: rAGMF_Monthly | FHL_Monthly | 800SWM)
A47: LOANINT-2503 | B47: 45747 | C47: Interest for Mar 2025 (lenders + 800S) | D47: =SUM(E47:G47) -> 25394.35 | E47: 8163.53 | F47: 8211.49 | G47: 9019.33 | H47: From the Loan & Interest Schedule (Tab name: rAGMF_Monthly | FHL_Monthly | 800SWM)
A48: LOANINT-2504 | B48: 45777 | C48: Interest for Apr 2025 (lenders + 800S) | D48: =SUM(E48:G48) -> 24370.38 | E48: 7817.34 | F48: 7824.66 | G48: 8728.38 | H48: From the Loan & Interest Schedule (Tab name: rAGMF_Monthly | FHL_Monthly | 800SWM)
A49: LOANINT-2505 | B49: 45808 | C49: Interest for May 2025 (lenders + 800S) | D49: =SUM(E49:G49) -> 25182.73 | E49: 8077.92 | F49: 8085.48 | G49: 9019.33 | H49: From the Loan & Interest Schedule (Tab name: rAGMF_Monthly | FHL_Monthly | 800SWM)
... A56: LOANINT-2512 | B56: 46022 | C56: Interest for Dec 2025 (lenders + 800S) | D56: =SUM(E56:G56) -> 24832.18 | E56: 7938.4 | F56: 7874.45 | G56: 9019.33 | H56: From the Loan & Interest Schedule (Tab name: rAGMF_Monthly | FHL_Monthly | 800SWM)
C57: Total | D57: =SUM(D17:D56) -> 1123293.3 | E57: =SUM(E17:E56) -> 481899.2 | F57: =SUM(F17:F56) -> 481082.8 | G57: =SUM(G17:G56) -> 160311.29 | H57: =IF(ROUND(D57-E57-F57-G57,2)=0,"Balanced","CHECK") -> Balanced
...

Sheet Before vs After
A1: Balances at 31-Dec-2024: QuickBooks now vs after clean-up
A2: Only the loan & interest part of each account is shown. Liabilities shown as positive = amount owed. Excludes optional Part C (WHT top-up).
A4: Account | B4: QuickBooks now | C4: After clean-up | D4: Change | E4: Explanation
A5: Balance sheet - what the company owes
A6: 20520 Related Party PNP-Holding (loan part only) | B6: 1470000 | C6: 0 | D6: =C6-B6 -> -1470000 | E6: Loans moved out: 3,000,000 received less 1,530,000 paid by 800S.
A7: Loan payable - responsAbility (NEW) | B7: 0 | C7: 735000 | D7: =C7-B7 -> 735000 | E7: 1,500,000 less 765,000 paid by 800S.
A8: Loan payable - Healthier (NEW) | B8: 0 | C8: 735000 | D8: =C8-B8 -> 735000 | E8: 1,500,000 less 765,000 paid by 800S.
A9: 20010 Operating Account Payable (lender interest part) | B9: 26536.09 | C9: 0 | D9: =C9-B9 -> -26536.09 | E9: Now: 316,881.39 guessed 2023 interest - 74,668.47 WHT - 215,676.83 LOAN24-001. After: nothing left in trade payables.
A10: 20259 Shareholder loan - 800SWM | B10: 1745676.8 | C10: ='Correcting Entries'!E8+'Correcting Entries'!E11 -> 1745676.8 | D10: =C10-B10 -> 0 | E10: No change in amount (only dates/accounts fixed).
A11: 20260 Interest payable - Healthier | B11: 156337.69 | C11: ='Correcting Entries'!F60+'Correcting Entries'!F61+'Correcting Entries'!F62-78155.75-106511.14 -> 201381.69 | D11: =C11-B11 -> 45044 | E11: Interest 2022-2024 less paid (Mar-2023 78,155.75 and 800S 106,511.14). = client file 201,381.69.
A12: 20261 Interest payable - responsAbility | B12: 171965.15 | C12: ='Correcting Entries'!E60+'Correcting Entries'!E61+'Correcting Entries'!E62-75648.08-109165.69 -> 201893.06 | D12: =C12-B12 -> 29927.91 | E12: Interest 2022-2024 less paid (Mar-2023 75,648.08 and 800S 109,165.69). = client file 201,893.06.
A13: 20262 Interest payable - 800SWM | B13: 54115.97 | C13: ='Correcting Entries'!G62 -> 54115.97 | D13: =C13-B13 -> 0 | E13: No change.
A14: Profit & loss - cost by year
A15: 66045 Interest Expense - 2022 | B15: 0 | C15: ='Correcting Entries'!D60 -> 94455.62 | D15: =C15-B15 -> 94455.62 | E15: 2022 interest was never booked.
A16: 66045 Interest Expense - 2023 | B16: 470685.22 | C16: ='Correcting Entries'!D61 -> 368774.94 | D16: =C16-B16 -> -101910.28 | E16: Guesses and the full Mar-2023 payment replaced by lender figures.
A17: 66045 Interest Expense - 2024 | B17: 382418.81 | C17: ='Correcting Entries'!D62 -> 363640.82 | D17: =C17-B17 -> -18777.99 | E17: Lender part lowered to actual lender rates; 800S part unchanged. (Excludes 744.96 overdraft interest.)
A18: 63025 WTH 14% Non Deductible - 2023 | B18: 0 | C18: 40281.18 | D18: =C18-B18 -> 40281.18 | E18: 14% WHT already paid, moved out of 20010.
A19: 63025 WTH 14% Non Deductible - 2024 | B19: 0 | C19: 34387.29 | D19: =C19-B19 -> 34387.29 | E19: 14% WHT already paid, moved out of 20010.
A21: CHECK: change in liabilities | D21: =D6+D7+D8+D9+D10+D11+D12+D13 -> 48435.82
A22: CHECK: change in costs (P&L) | D22: =D15+D16+D17+D18+D19 -> 48435.82
A23: Difference (must be 0) | D23: =ROUND(D21-D22,2) -> 0 | E23: Every extra dollar owed = an extra dollar of cost, so the clean-up balances.
A25: Tie-out to client file (lender interest owed at 31-Dec-2024)
A26: responsAbility - after clean-up | C26: =C12 -> 201893.06
A27: responsAbility - client file (Year_End_Totals) | C27: 201893.06
A28: Difference | C28: =ROUND(C26-C27,2) -> 0
A29: Healthier - after clean-up | C29: =C11 -> 201381.69
A30: Healthier - client file (Year_End_Totals) | C30: 201381.69
A31: Difference | C31: =ROUND(C29-C30,2) -> 0

Sheet Option B - Locked Years
A1: Option B - if 2022 and 2023 are already closed / audited
A2: Do NOT touch 2022-2023 transactions. Fix everything in one catch-up entry dated 01-Jan-2024. The 31-Dec-2024 balances end up exactly the same as Option A.
A4: Step 1 - In tab 2, only do these:
A5: • | B5: DELETE: INT24-001 to INT24-012, LOAN24-001, LOAN24-002 (all 2024).
A6: • | B6: EDIT: the 2024 WHT entries only (JAN24-002, FEB24-002, MAR24-031, APR24-030, MAY24-031, JUN24-030, JUL24-031): change the 20010 WHT line to 63025.
A7: • | B7: Skip all 2022 and 2023 deletes/edits.
A9: Step 2 - Post these 2 catch-up entries dated 01-Jan-2024
A10: Entry | B10: Date | C10: Account | D10: Debit | E10: Credit | F10: Why
A11: OB-01 | B11: 45292 | C11: 20520 Related Party PNP-Holding | D11: 3000000 | F11: Take the loans out of the related-party account.
A12: OB-01 | B12: 45292 | C12: Loan payable - responsAbility (NEW) | E12: 1500000 | F12: Loan owed to rA.
A13: OB-01 | B13: 45292 | C13: Loan payable - Healthier (NEW) | E13: 1500000 | F13: Loan owed to Healthier.
A14: OB-02 | B14: 45292 | C14: 20010 Operating Account Payable | D14: 276600.21 | F14: Clear the 2023 interest left in trade payables (316,881.39 guesses less 40,281.18 WHT).
A15: OB-02 | B15: 45292 | C15: Retained Earnings (prior-year adjustment) | D15: 32826.52 | F15: Net effect on 2022-2023 profit: interest +94,455.62 (2022) -101,910.28 (2023) + WHT cost 40,281.18.
A16: OB-02 | B16: 45292 | C16: 20261 Interest payable - responsAbility | E16: 156352.56 | F16: Owed to rA at 31-Dec-2023 (client file).
A17: OB-02 | B17: 45292 | C17: 20260 Interest payable - Healthier | E17: 153074.17 | F17: Owed to Healthier at 31-Dec-2023 (client file).
C18: Total | D18: =SUM(D11:D17) -> 3309426.7 | E18: =SUM(E11:E17) -> 3309426.7 | F18: =IF(ROUND(D18-E18,2)=0,"Balanced","CHECK") -> Balanced
A20: Step 3 - Then post from tab 3:
A21: • | B21: Part A (CE-01 and CE-02) - same as Option A.
A22: • | B22: Part B - ONLY the 2024 rows (LOANINT-2401 to LOANINT-2412). Skip the 2022-2023 rows.
A23: • | B23: Part C (optional WHT) - the 2022 and 2023 rows would also go to Retained Earnings instead of 63025.
A24: • | B24: Tell the auditors: this is a prior-period correction (2022-2023 interest and loan classification).
